actor_name: Clone
base_link_leveller: {child_frame: base_link, parent_frame: odom}
battery_max_voltage: 50.4
battery_min_voltage: 40.0
battery_warn_voltage: 42.0
body_tracks_alignment: -0.0025
bullet_api: {address: 'https://ctu-robot-bullet', compute_rates: true, password: tradrtradr,
  rate: 0.1, type: bullet_ac, username: robot}
calibrated_joints:
  d435: [0.0, 0.0, 0.0, 0.015, -0.005, 0.0, realsense_holder_part2, camera_back_mounting_plane]
  dgps_aux_antenna: [0.57, 0.1215, 0.35, 0.0, 0.0, 0.0, rear_right_box, dgps_aux_antenna]
  dgps_main_antenna: [0.03, 0.07, 0.4, 0.0, 0.0, 0.0, rear_right_box, dgps_main_antenna]
  ouster: [-0.0065, 0.0, 0.256, 0.01, 0.01, 0.75, ouster_base, os_sensor]
  ouster_base: [-0.02, 0.0, 0.0, 0.0, 0.263, 0.0, ouster_holder, ouster_base]
  ouster_holder: [0.08, 0.0, 0.005, 0.0, 0.0, 0.0, omnicam_top, ouster_holder]
  t265: [-0.01101015, -0.00626623, 0.2895825, 0.0, 0.0, -1.5758, rear_sensor_item,
    t265_pose_frame]
camera_front:
  allow_lossy_compression: true
  camera_frame: camera_0
  camera_info_url: package://cras_basler_camera/calibrations/${NAME}.yaml
  compression_beyond_ratio: 70.0
  debayer: {debayer: 0}
  device_user_id: '40113912'
  enable_current_params_publisher: false
  enable_status_publisher: false
  frame_rate: 5.0
  gige: {mtu_size: 1500}
  grab_strategy: 1
  grab_timeout: 210
  image_bayer_rect:
    compressed: {format: jpeg, jpeg_quality: 80, png_level: 9}
    compressedDepth: {depth_max: 10.0, depth_quantization: 100.0, png_level: 1}
    h264: {crf: 30, max_rate: 60.0, width: 640}
    theora: {keyframe_frequency: 64, optimize_for: 1, quality: 31, target_bitrate: 800000}
  image_color:
    compressed: {format: jpeg, jpeg_quality: 80, png_level: 9}
    compressedDepth: {depth_max: 10.0, depth_quantization: 100.0, png_level: 1}
    h264: {crf: 30, max_rate: 60.0, width: 640}
    theora: {keyframe_frequency: 64, optimize_for: 1, quality: 31, target_bitrate: 800000}
  image_encoding: bayer_rggb8
  image_mono:
    compressed: {format: jpeg, jpeg_quality: 80, png_level: 9}
    compressedDepth: {depth_max: 10.0, depth_quantization: 100.0, png_level: 1}
    h264: {crf: 30, max_rate: 60.0, width: 640}
    theora: {keyframe_frequency: 64, optimize_for: 1, quality: 31, target_bitrate: 800000}
  image_raw:
    compressed: {format: jpeg, jpeg_quality: 80, png_level: 9}
    compressedDepth: {depth_max: 10.0, depth_quantization: 100.0, png_level: 1}
    h264: {crf: 30, max_rate: 60.0, width: 640}
    theora: {keyframe_frequency: 64, optimize_for: 1, quality: 31, target_bitrate: 800000}
  image_rect:
    compressed: {format: jpeg, jpeg_quality: 80, png_level: 9}
    compressedDepth: {depth_max: 10.0, depth_quantization: 100.0, png_level: 1}
    h264: {crf: 30, max_rate: 60.0, width: 640}
    theora: {keyframe_frequency: 64, optimize_for: 1, quality: 31, target_bitrate: 800000}
  ptp_delay_mechanism: E2E
  ptp_enable_management: true
  ptp_enable_two_step: false
  ptp_network_mode: multicast
  ptp_priority1: 240
  ptp_profile: e2e-default
  rectify: {interpolation: 1}
  run_ptp: true
  startup_user_set: UserSet1
  timestamp_mode: cam_simple
  trigger_source: line1
  trigger_timeout: 500
camera_left:
  allow_lossy_compression: true
  camera_frame: camera_3
  camera_info_url: package://cras_basler_camera/calibrations/${NAME}.yaml
  compression_beyond_ratio: 70.0
  debayer: {debayer: 0}
  device_user_id: '40113577'
  enable_current_params_publisher: false
  enable_status_publisher: false
  frame_rate: 5.0
  gige: {mtu_size: 1500}
  grab_strategy: 1
  grab_timeout: 210
  image_bayer_rect:
    compressed: {format: jpeg, jpeg_quality: 80, png_level: 9}
    compressedDepth: {depth_max: 10.0, depth_quantization: 100.0, png_level: 1}
    h264: {crf: 30, max_rate: 60.0, width: 640}
    theora: {keyframe_frequency: 64, optimize_for: 1, quality: 31, target_bitrate: 800000}
  image_color:
    compressed: {format: jpeg, jpeg_quality: 80, png_level: 9}
    compressedDepth: {depth_max: 10.0, depth_quantization: 100.0, png_level: 1}
    h264: {crf: 30, max_rate: 60.0, width: 640}
    theora: {keyframe_frequency: 64, optimize_for: 1, quality: 31, target_bitrate: 800000}
  image_encoding: bayer_rggb8
  image_mono:
    compressed: {format: jpeg, jpeg_quality: 80, png_level: 9}
    compressedDepth: {depth_max: 10.0, depth_quantization: 100.0, png_level: 1}
    h264: {crf: 30, max_rate: 60.0, width: 640}
    theora: {keyframe_frequency: 64, optimize_for: 1, quality: 31, target_bitrate: 800000}
  image_raw:
    compressed: {format: jpeg, jpeg_quality: 80, png_level: 9}
    compressedDepth: {depth_max: 10.0, depth_quantization: 100.0, png_level: 1}
    h264: {crf: 30, max_rate: 60.0, width: 640}
    theora: {keyframe_frequency: 64, optimize_for: 1, quality: 31, target_bitrate: 800000}
  image_rect:
    compressed: {format: jpeg, jpeg_quality: 80, png_level: 9}
    compressedDepth: {depth_max: 10.0, depth_quantization: 100.0, png_level: 1}
    h264: {crf: 30, max_rate: 60.0, width: 640}
    theora: {keyframe_frequency: 64, optimize_for: 1, quality: 31, target_bitrate: 800000}
  ptp_delay_mechanism: E2E
  ptp_enable_management: true
  ptp_enable_two_step: false
  ptp_network_mode: multicast
  ptp_priority1: 240
  ptp_profile: e2e-default
  rectify: {interpolation: 1}
  run_ptp: true
  startup_user_set: UserSet1
  timestamp_mode: cam_simple
  trigger_source: line1
  trigger_timeout: 500
camera_rear:
  allow_lossy_compression: true
  camera_frame: camera_2
  camera_info_url: package://cras_basler_camera/calibrations/${NAME}.yaml
  compression_beyond_ratio: 70.0
  debayer: {debayer: 0}
  device_user_id: '40113575'
  enable_current_params_publisher: false
  enable_status_publisher: false
  frame_rate: 5.0
  gige: {mtu_size: 1500}
  grab_strategy: 1
  grab_timeout: 210
  image_bayer_rect:
    compressed: {format: jpeg, jpeg_quality: 80, png_level: 9}
    compressedDepth: {depth_max: 10.0, depth_quantization: 100.0, png_level: 1}
    h264: {crf: 30, max_rate: 60.0, width: 640}
    theora: {keyframe_frequency: 64, optimize_for: 1, quality: 31, target_bitrate: 800000}
  image_color:
    compressed: {format: jpeg, jpeg_quality: 80, png_level: 9}
    compressedDepth: {depth_max: 10.0, depth_quantization: 100.0, png_level: 1}
    h264: {crf: 30, max_rate: 60.0, width: 640}
    theora: {keyframe_frequency: 64, optimize_for: 1, quality: 31, target_bitrate: 800000}
  image_encoding: bayer_rggb8
  image_mono:
    compressed: {format: jpeg, jpeg_quality: 80, png_level: 9}
    compressedDepth: {depth_max: 10.0, depth_quantization: 100.0, png_level: 1}
    h264: {crf: 30, max_rate: 60.0, width: 640}
    theora: {keyframe_frequency: 64, optimize_for: 1, quality: 31, target_bitrate: 800000}
  image_raw:
    compressed: {format: jpeg, jpeg_quality: 80, png_level: 9}
    compressedDepth: {depth_max: 10.0, depth_quantization: 100.0, png_level: 1}
    h264: {crf: 30, max_rate: 60.0, width: 640}
    theora: {keyframe_frequency: 64, optimize_for: 1, quality: 31, target_bitrate: 800000}
  image_rect:
    compressed: {format: jpeg, jpeg_quality: 80, png_level: 9}
    compressedDepth: {depth_max: 10.0, depth_quantization: 100.0, png_level: 1}
    h264: {crf: 30, max_rate: 60.0, width: 640}
    theora: {keyframe_frequency: 64, optimize_for: 1, quality: 31, target_bitrate: 800000}
  ptp_delay_mechanism: E2E
  ptp_enable_management: true
  ptp_enable_two_step: false
  ptp_network_mode: multicast
  ptp_priority1: 240
  ptp_profile: e2e-default
  rectify: {interpolation: 1}
  run_ptp: true
  startup_user_set: UserSet1
  timestamp_mode: cam_simple
  trigger_source: line1
  trigger_timeout: 500
camera_right:
  allow_lossy_compression: true
  camera_frame: camera_1
  camera_info_url: package://cras_basler_camera/calibrations/${NAME}.yaml
  compression_beyond_ratio: 70.0
  debayer: {debayer: 0}
  device_user_id: '40113899'
  enable_current_params_publisher: false
  enable_status_publisher: false
  frame_rate: 5.0
  gige: {mtu_size: 1500}
  grab_strategy: 1
  grab_timeout: 210
  image_bayer_rect:
    compressed: {format: jpeg, jpeg_quality: 80, png_level: 9}
    compressedDepth: {depth_max: 10.0, depth_quantization: 100.0, png_level: 1}
    h264: {crf: 30, max_rate: 60.0, width: 640}
    theora: {keyframe_frequency: 64, optimize_for: 1, quality: 31, target_bitrate: 800000}
  image_color:
    compressed: {format: jpeg, jpeg_quality: 80, png_level: 9}
    compressedDepth: {depth_max: 10.0, depth_quantization: 100.0, png_level: 1}
    h264: {crf: 30, max_rate: 60.0, width: 640}
    theora: {keyframe_frequency: 64, optimize_for: 1, quality: 31, target_bitrate: 800000}
  image_encoding: bayer_rggb8
  image_mono:
    compressed: {format: jpeg, jpeg_quality: 80, png_level: 9}
    compressedDepth: {depth_max: 10.0, depth_quantization: 100.0, png_level: 1}
    h264: {crf: 30, max_rate: 60.0, width: 640}
    theora: {keyframe_frequency: 64, optimize_for: 1, quality: 31, target_bitrate: 800000}
  image_raw:
    compressed: {format: jpeg, jpeg_quality: 80, png_level: 9}
    compressedDepth: {depth_max: 10.0, depth_quantization: 100.0, png_level: 1}
    h264: {crf: 30, max_rate: 60.0, width: 640}
    theora: {keyframe_frequency: 64, optimize_for: 1, quality: 31, target_bitrate: 800000}
  image_rect:
    compressed: {format: jpeg, jpeg_quality: 80, png_level: 9}
    compressedDepth: {depth_max: 10.0, depth_quantization: 100.0, png_level: 1}
    h264: {crf: 30, max_rate: 60.0, width: 640}
    theora: {keyframe_frequency: 64, optimize_for: 1, quality: 31, target_bitrate: 800000}
  ptp_delay_mechanism: E2E
  ptp_enable_management: true
  ptp_enable_two_step: false
  ptp_network_mode: multicast
  ptp_priority1: 240
  ptp_profile: e2e-default
  rectify: {interpolation: 1}
  run_ptp: true
  startup_user_set: UserSet1
  timestamp_mode: cam_simple
  trigger_source: line1
  trigger_timeout: 500
camera_up:
  allow_lossy_compression: true
  camera_frame: pylon_camera_up
  camera_info_url: package://cras_basler_camera/calibrations/${NAME}.yaml
  compression_beyond_ratio: 70.0
  debayer: {debayer: 0}
  device_user_id: '40113927'
  enable_current_params_publisher: false
  enable_status_publisher: false
  frame_rate: 5.0
  gige: {mtu_size: 1500}
  grab_strategy: 1
  grab_timeout: 210
  image_bayer_rect:
    compressed: {format: jpeg, jpeg_quality: 80, png_level: 9}
    compressedDepth: {depth_max: 10.0, depth_quantization: 100.0, png_level: 1}
    h264: {crf: 30, max_rate: 60.0, width: 640}
    theora: {keyframe_frequency: 64, optimize_for: 1, quality: 31, target_bitrate: 800000}
  image_color:
    compressed: {format: jpeg, jpeg_quality: 80, png_level: 9}
    compressedDepth: {depth_max: 10.0, depth_quantization: 100.0, png_level: 1}
    h264: {crf: 30, max_rate: 60.0, width: 640}
    theora: {keyframe_frequency: 64, optimize_for: 1, quality: 31, target_bitrate: 800000}
  image_encoding: bayer_rggb8
  image_mono:
    compressed: {format: jpeg, jpeg_quality: 80, png_level: 9}
    compressedDepth: {depth_max: 10.0, depth_quantization: 100.0, png_level: 1}
    h264: {crf: 30, max_rate: 60.0, width: 640}
    theora: {keyframe_frequency: 64, optimize_for: 1, quality: 31, target_bitrate: 800000}
  image_raw:
    compressed: {format: jpeg, jpeg_quality: 80, png_level: 9}
    compressedDepth: {depth_max: 10.0, depth_quantization: 100.0, png_level: 1}
    h264: {crf: 30, max_rate: 60.0, width: 640}
    theora: {keyframe_frequency: 64, optimize_for: 1, quality: 31, target_bitrate: 800000}
  image_rect:
    compressed: {format: jpeg, jpeg_quality: 80, png_level: 9}
    compressedDepth: {depth_max: 10.0, depth_quantization: 100.0, png_level: 1}
    h264: {crf: 30, max_rate: 60.0, width: 640}
    theora: {keyframe_frequency: 64, optimize_for: 1, quality: 31, target_bitrate: 800000}
  ptp_delay_mechanism: E2E
  ptp_enable_management: true
  ptp_enable_two_step: false
  ptp_network_mode: multicast
  ptp_priority1: 240
  ptp_profile: e2e-default
  rectify: {interpolation: 1}
  run_ptp: true
  startup_user_set: UserSet1
  timestamp_mode: cam_simple
  trigger_source: line1
  trigger_timeout: 500
cloud_to_cloud_filtering:
  cloud_filter_chain:
  - name: body_filter
    params:
      body_model/inflation/padding: 0.01
      body_model/inflation/per_link/padding: {'antenna::contains': 0.08, 'base_link::0::contains': 0.07,
        'front_left_flipper::contains': 0.05, 'front_right_flipper::contains': 0.05,
        'mobilicom_antenna_l::contains': 0.07, 'mobilicom_antenna_r::contains': 0.07,
        'rear_left_flipper::contains': 0.03, 'rear_right_flipper::contains': 0.03}
      body_model/inflation/scale: 1.01
      body_model/robot_description_param: /nifti_robot_description
      bounding_box/compute: true
      bounding_box/debug: true
      bounding_box/marker: true
      bounding_box/publish_cut_out_pointcloud: true
      bounding_sphere/compute: true
      bounding_sphere/debug: true
      bounding_sphere/marker: true
      bounding_sphere/publish_cut_out_pointcloud: true
      debug/marker/bounding_box: true
      debug/marker/bounding_sphere: true
      debug/marker/contains: true
      debug/marker/shadow: true
      debug/pcl/clip: true
      debug/pcl/inside: true
      debug/pcl/shadow: true
      filter/do_clipping: true
      filter/do_shadow_test: true
      filter/max_shadow_distance: 1.0
      frames/filtering: os_lidar
      frames/sensor: os_lidar
      ignored_links/contains_test: [battery]
      ignored_links/shadow_test: [os_sensor, ouster_holder, 'base_link::big_collision_box',
        battery, battery_cover, 'base_link::1', 'base_link::2', 'base_link::3', 'base_link::4',
        'base_link::5', 'base_link::6', 'base_link::7']
      sensor/max_distance: 50.0
      sensor/min_distance: 0.07
      sensor/point_by_point: false
    type: robot_body_filter/RobotBodyFilterPointCloud2
  disabled_filters: ''
  max_age: 3600.0
  publish_each_filter: false
compass: {publish_mag_azimuth_ned_deg: true, publish_mag_unbiased: true, publish_true_azimuth_enu_rad: true,
  publish_utm_azimuth_enu_rad: true}
display: {device: /dev/ttyUSB0}
dynamic_robot_model_server: {axis_x_offset: 0.059, axis_y_offset: 0.08, battery_cover_height: 0.067,
  battery_cover_x: 0.225, battery_mass: 2.7, big_collision_box_height: 0.35, big_collision_box_length: 0.6,
  big_collision_box_on_top: true, big_collision_box_width: 0.5, big_collision_box_x: 0.0,
  body_mass: 10.0, camera_front_pos_x: 0.6, camera_front_pos_y: 0.1215, camera_front_pos_z: 0.02,
  camera_front_quat_w: 1.0, camera_front_quat_x: 0.0, camera_front_quat_y: 0.0, camera_front_quat_z: 0.0,
  camera_front_rpy_p: -0.0, camera_front_rpy_r: 0.0, camera_front_rpy_y: 0.0, camera_left_pos_x: 0.3,
  camera_left_pos_y: 0.223, camera_left_pos_z: 0.02, camera_left_quat_w: 0.7071, camera_left_quat_x: 0.0,
  camera_left_quat_y: 0.0, camera_left_quat_z: 0.7071, camera_left_rpy_p: -0.0, camera_left_rpy_r: 0.0,
  camera_left_rpy_y: 1.5707963267948966, camera_rear_pos_x: 0.02, camera_rear_pos_y: 0.1215,
  camera_rear_pos_z: 0.02, camera_rear_quat_w: 0.0, camera_rear_quat_x: 0.0, camera_rear_quat_y: 0.0,
  camera_rear_quat_z: 1.0, camera_rear_rpy_p: -0.0, camera_rear_rpy_r: 0.0, camera_rear_rpy_y: 3.141592653589793,
  camera_right_pos_x: 0.3, camera_right_pos_y: 0.02, camera_right_pos_z: 0.02, camera_right_quat_w: -0.7071,
  camera_right_quat_x: 0.0, camera_right_quat_y: 0.0, camera_right_quat_z: 0.7071,
  camera_right_rpy_p: -0.0, camera_right_rpy_r: 0.0, camera_right_rpy_y: -1.5707963267948966,
  camera_top_pos_x: 0.48, camera_top_pos_y: 0.1215, camera_top_pos_z: 0.25, camera_top_quat_w: -0.7071,
  camera_top_quat_x: 0.0, camera_top_quat_y: 0.7071, camera_top_quat_z: 0.0, camera_top_rpy_p: -1.5707963267948966,
  camera_top_rpy_r: -0.0, camera_top_rpy_y: 0.0, d435_pos_x: 0.0, d435_pos_y: 0.0,
  d435_pos_z: 0.0, d435_quat_w: 0.9999687502213535, d435_quat_x: 0.007499906250429686,
  d435_quat_y: -0.002499927083736978, d435_quat_z: 1.8749804688183592e-05, d435_rpy_p: -0.005,
  d435_rpy_r: 0.015, d435_rpy_y: 0.0, dgps_antenna_height: 0.083, dgps_antenna_radius: 0.02,
  dgps_aux_antenna_pos_x: 0.57, dgps_aux_antenna_pos_y: 0.1215, dgps_aux_antenna_pos_z: 0.35,
  dgps_aux_antenna_quat_w: 1.0, dgps_aux_antenna_quat_x: 0.0, dgps_aux_antenna_quat_y: 0.0,
  dgps_aux_antenna_quat_z: 0.0, dgps_aux_antenna_rpy_p: 0.0, dgps_aux_antenna_rpy_r: 0.0,
  dgps_aux_antenna_rpy_y: 0.0, dgps_main_antenna_pos_x: 0.03, dgps_main_antenna_pos_y: 0.07,
  dgps_main_antenna_pos_z: 0.4, dgps_main_antenna_quat_w: 1.0, dgps_main_antenna_quat_x: 0.0,
  dgps_main_antenna_quat_y: 0.0, dgps_main_antenna_quat_z: 0.0, dgps_main_antenna_rpy_p: 0.0,
  dgps_main_antenna_rpy_r: 0.0, dgps_main_antenna_rpy_y: 0.0, flipper_inflation_ratio: 1.5,
  flipper_inward_enlargement: 0.0, gps_antenna_disc_radius: 0.05, gps_antenna_height: 0.4,
  gps_antenna_radius: 0.03, has_axis_camera: false, has_battery_cover: true, has_dgps_antennas: true,
  has_directional_gps_antennas: false, has_flipper_touch_sensors: false, has_gps_antenna: true,
  has_jetson: false, has_mobilicom: false, has_mote_deployer: false, has_new_realsense: false,
  has_omnicam: false, has_omnicam_sensor_mount: false, has_omnicam_vras: true, has_ouster_lidar: true,
  has_ptuxthermo: false, has_realsense: false, has_realsense_d435: false, has_realsense_t265: false,
  has_rear_sensor_item: false, has_sick_lidar: false, has_top_box: true, has_velodyne: false,
  jetson_shift_x: 0.515, jetson_shift_y: 0.145, jetson_version: 1, jetson_yaw: 0.0,
  laser_pitch: 0.0, mobilicom_antenna_l_rotation: -0.5, mobilicom_antenna_l_tilt: 1.0,
  mobilicom_antenna_r_rotation: 0.0, mobilicom_antenna_r_tilt: 1.5758, mobilicom_antennas_length: 0.17,
  mobilicom_has_antenna_box: false, mobilicom_is_lite: true, mobilicom_parent_link: rear_right_box,
  mobilicom_pitch: 4.0, mobilicom_roll: 1.5758, mobilicom_shift_x: 0.0, mobilicom_shift_y: 0.01,
  mobilicom_shift_z: 0.2, mobilicom_yaw: 3.14152, ouster_base_pos_x: -0.02, ouster_base_pos_y: 0.0,
  ouster_base_pos_z: 0.0, ouster_base_quat_w: 0.9913663270668565, ouster_base_quat_x: 0.0,
  ouster_base_quat_y: 0.13112133906413045, ouster_base_quat_z: 0.0, ouster_base_rpy_p: 0.263,
  ouster_base_rpy_r: 0.0, ouster_base_rpy_y: 0.0, ouster_holder_pos_x: 0.08, ouster_holder_pos_y: 0.0,
  ouster_holder_pos_z: 0.005, ouster_holder_quat_w: 1.0, ouster_holder_quat_x: 0.0,
  ouster_holder_quat_y: 0.0, ouster_holder_quat_z: 0.0, ouster_holder_rpy_p: 0.0,
  ouster_holder_rpy_r: 0.0, ouster_holder_rpy_y: 0.0, ouster_pos_x: -0.0065, ouster_pos_y: 0.0,
  ouster_pos_z: 0.256, ouster_quat_w: 0.9304935161525422, ouster_quat_x: 0.002821128444775362,
  ouster_quat_y: 0.00648379269051955, ouster_quat_z: 0.3662401098524342, ouster_rpy_p: 0.01,
  ouster_rpy_r: 0.01, ouster_rpy_y: 0.75, ptuxthermo_x_offset: 0.2, ptuxthermo_y_offset: 0.18,
  realsense_holder_version: 1, realsense_parent_link: omnicam, realsense_roll: 0.0,
  realsense_shift_x: 0.0, realsense_shift_y: 0.0, realsense_shift_z: 0.0, realsense_tilt: -1.15,
  realsense_yaw: 0.62831853, revision: 2021, robot_description: '<?xml version="1.0"
    ?><robot name="NIFTi"><link name="rear_right_box"/><joint name="rear_right_box_j"
    type="fixed"><parent link="base_link"/><child link="rear_right_box"/><origin rpy="0
    0 0" xyz="-0.3175 -0.1215 0.185"/></joint><link name="os_sensor"><visual><geometry><mesh
    filename="package://cras_ouster_description/meshes/ouster-os0.dae"/></geometry></visual><collision><origin
    rpy="0 0 0" xyz="0 0 0.03675"/><geometry><cylinder length="0.0735" radius="0.0435"/></geometry></collision><inertial><mass
    value="0.5"/><origin xyz="0 0 0.03675"/><inertia ixx="0.000461625" ixy="0.0" ixz="0.0"
    iyy="0.000461625" iyz="0.0" izz="0.0004730625"/></inertial></link><joint name="ouster_holder_j"
    type="fixed"><parent link="top_box"/><child link="ouster_holder"/><origin rpy="0.0
    0.0 0.0" xyz="0.08 0.0 0.005"/></joint><!-- workaround for https://github.com/osrf/sdformat/issues/378
    --><gazebo reference="ouster_holder_j"><preserveFixedJoint>true</preserveFixedJoint></gazebo><joint
    name="ouster_base_j" type="fixed"><parent link="ouster_holder"/><child link="ouster_base"/><origin
    rpy="0.0 0.263 0.0" xyz="-0.02 0.0 0.0"/></joint><!-- workaround for https://github.com/osrf/sdformat/issues/378
    --><gazebo reference="ouster_base_j"><preserveFixedJoint>true</preserveFixedJoint></gazebo><joint
    name="ouster_j" type="fixed"><parent link="ouster_base"/><child link="os_sensor"/><origin
    rpy="0.01 0.01 0.75" xyz="-0.0065 0.0 0.256"/></joint><!-- workaround for https://github.com/osrf/sdformat/issues/378
    --><gazebo reference="ouster_j"><preserveFixedJoint>true</preserveFixedJoint></gazebo><link
    name="ouster_base"><inertial><origin rpy="0 0 0" xyz="0 0 0"/><mass value="1e-5"/><inertia
    ixx="1e-3" ixy="1e-6" ixz="1e-6" iyy="1e-3" iyz="1e-6" izz="1e-3"/></inertial></link><link
    name="ouster_holder"><inertial><origin rpy="0 0 0" xyz="0 0 0"/><mass value="1e-5"/><inertia
    ixx="1e-3" ixy="1e-6" ixz="1e-6" iyy="1e-3" iyz="1e-6" izz="1e-3"/></inertial></link><link
    name="base_link"><visual><origin rpy="0 0 0" xyz="0 0 0"/><geometry><mesh filename="package://nifti_robot_description/meshes/body_2021.dae"
    scale="1.0 1.0 1.0"/></geometry></visual><collision><origin rpy="0 0 0" xyz="0.000000
    0 0.1395"/><geometry><box size="0.635000 0.243000 0.108"/></geometry></collision><collision><origin
    rpy="0 0 0" xyz="0 0.135 0.09"/><geometry><box size="0.055 0.040 0.08"/></geometry></collision><collision><origin
    rpy="0 0 0" xyz="0 0.155 0.013"/><geometry><box size="0.055 0.020 0.075"/></geometry></collision><collision><origin
    rpy="0 0 0" xyz="0 -0.135 0.09"/><geometry><box size="0.055 0.040 0.08"/></geometry></collision><collision><origin
    rpy="0 0 0" xyz="0 -0.155 0.013"/><geometry><box size="0.055 0.020 0.075"/></geometry></collision><collision><origin
    rpy="0 0 0" xyz="0 0 0.0655"/><geometry><box size="0.565 0.243000 0.035000"/></geometry></collision><collision><origin
    rpy="1.57079632679 0 0" xyz="0.2825 0 0.083"/><geometry><cylinder length="0.243000"
    radius="0.035035"/></geometry></collision><collision><origin rpy="1.57079632679
    0 0" xyz="-0.2825 0 0.083"/><geometry><cylinder length="0.243000" radius="0.035035"/></geometry></collision><collision
    name="big_collision_box"><origin rpy="0 0 0" xyz="0.0 0 0.255"/><geometry><box
    size="0.6 0.5 0.35"/></geometry></collision><inertial><origin rpy="0 0 0" xyz="-0.034
    0 0.142"/><mass value="6.746"/><inertia ixx="0.0069904" ixy="0.00012271" ixz="-4.2725e-05"
    iyy="0.02129" iyz="-0.00010522" izz="0.025519"/></inertial></link><link name="battery"><visual><origin
    rpy="0 0 0" xyz="0 0 0"/><geometry><mesh filename="package://nifti_robot_description/meshes/battery.dae"
    scale="1.0 1.0 1.0"/></geometry></visual><collision><origin rpy="0 0 0" xyz="0
    0 0.0410"/><geometry><box size="0.1450 0.1350 0.0820"/></geometry></collision><inertial><origin
    rpy="0 0 0" xyz="0 0 0.041"/><mass value="3.18"/><inertia ixx="0.0020793" ixy="0.0"
    ixz="0.0" iyy="0.0023127" iyz="0.0" izz="0.0032712"/></inertial></link><joint
    name="battery_j" type="fixed"><parent link="base_link"/><child link="battery"/><origin
    rpy="0 1.57079632679 0" xyz="-0.105 0 0.12"/></joint><link name="battery_cover"><visual><origin
    xyz="0 0 0.0335"/><geometry><box size="0.13 0.185 0.067"/></geometry><material
    name="body_color"><color rgba="0 0.36862745098 0.721568627451 1.0"/></material></visual><collision><origin
    xyz="0 0 0.0335"/><geometry><box size="0.13 0.185 0.067"/></geometry></collision></link><joint
    name="battery_cover_j" type="fixed"><parent link="rear_right_box"/><child link="battery_cover"/><origin
    rpy="0 0 0" xyz="0.225 0.1215 0.0"/></joint><link name="top_box"><visual><origin
    rpy="0 0 0" xyz="0 0 0"/><geometry><mesh filename="package://nifti_robot_description/meshes/top_box_2021_ladybug.dae"
    scale="1.0 1.0 1.0"/></geometry></visual><collision><origin rpy="0 0 0" xyz="0
    0 0.0485"/><geometry><box size="0.18 0.233 0.097"/></geometry></collision><collision><origin
    rpy="0 0 0" xyz="-0.04 0.09 0.0690"/><geometry><box size="0.0440 0.0440 0.01303"/></geometry></collision><collision><origin
    rpy="0 0 0" xyz="0.01474 -0.08352 0.07996"/><geometry><box size="0.03732 0.03523
    0.03489"/></geometry></collision><visual><origin rpy="0.0 0 0" xyz="-0.1 -0.1
    0.135"/><geometry><cylinder length="0.11" radius="0.01"/></geometry><material
    name="black_color"><color rgba="0.0 0.0 0.0 1.0"/></material></visual><collision><origin
    rpy="0.0 0 0" xyz="-0.1 -0.1 0.135"/><geometry><cylinder length="0.11" radius="0.01"/></geometry></collision><visual><origin
    rpy="0.0 0 0" xyz="0.1 0.047 0.085"/><geometry><cylinder length="0.13" radius="0.01"/></geometry><material
    name="black_color"><color rgba="0.0 0.0 0.0 1.0"/></material></visual><collision><origin
    rpy="0.0 0 0" xyz="0.1 0.047 0.085"/><geometry><cylinder length="0.13" radius="0.01"/></geometry></collision><visual><origin
    rpy="0.0 0 0" xyz="0.1 -0.047 0.085"/><geometry><cylinder length="0.13" radius="0.01"/></geometry><material
    name="black_color"><color rgba="0.0 0.0 0.0 1.0"/></material></visual><collision><origin
    rpy="0.0 0 0" xyz="0.1 -0.047 0.085"/><geometry><cylinder length="0.13" radius="0.01"/></geometry></collision><inertial><origin
    rpy="0 0 0" xyz="0 0 0.041"/><mass value="0.24"/><inertia ixx="0.0026136" ixy="0.0"
    ixz="0.0" iyy="0.0049426" iyz="0.0" izz="0.0070334"/></inertial></link><joint
    name="top_box_j" type="fixed"><parent link="rear_right_box"/><child link="top_box"/><origin
    rpy="0 0 0" xyz="0.414 0.1215 0.0"/></joint><link name="top_box_step"><visual><origin
    rpy="0 0 0" xyz="0 0 0.05"/><geometry><box size="0.1270 0.12 0.1"/></geometry><material
    name="body_color"><color rgba="0 0.36862745098 0.721568627451 1.0"/></material></visual><visual><origin
    rpy="0 0.01 0" xyz="-0.0165 0 0.181"/><geometry><cylinder length="0.05" radius="0.025"/></geometry><material
    name="body_color"><color rgba="0 0.36862745098 0.721568627451 1.0"/></material></visual><collision><origin
    rpy="0 0 0" xyz="0 0 0.05"/><geometry><box size="0.1270 0.12 0.1"/></geometry></collision><inertial><mass
    value="1.0"/><origin xyz="0 0 0.05"/><inertia ixx="0.00217741666667" ixy="0.0"
    ixz="0.0" iyy="0.00254408333333" iyz="0.0" izz="0.00203333333333"/></inertial></link><joint
    name="top_box_step_j" type="fixed"><parent link="top_box"/><child link="top_box_step"/><origin
    rpy="0 0 0" xyz="0 0 0.06252"/></joint><link name="antenna"><visual><origin rpy="0
    0 0" xyz="0 0 0"/><geometry><mesh filename="package://nifti_robot_description/meshes/antenna.dae"
    scale="1.0 1.0 1.0"/></geometry></visual><collision><origin rpy="0 1.57079632679
    0" xyz="-0.01864 0 0"/><geometry><cylinder length="0.03718" radius="0.008"/></geometry></collision><collision><origin
    rpy="0 0 0" xyz="-0.030 0 0.19053"/><geometry><cylinder length="0.38107" radius="0.008"/></geometry></collision><inertial><origin
    rpy="0 0 0" xyz="-0.022 0.0203 0.02917"/><mass value="0.56"/><inertia ixx="0.004878"
    ixy="-6.2341e-07" ixz="-7.4538e-07" iyy="0.00090164" iyz="-0.00014394" izz="0.0042946"/></inertial></link><joint
    name="antenna_j" type="fixed"><parent link="base_link"/><child link="antenna"/><origin
    rpy="0 0 0" xyz="-0.1975 0.1 0.1551"/></joint><link name="gps_antenna"><visual><origin
    rpy="0 0 0" xyz="0 0 0.0"/><geometry><cylinder length="0.01" radius="0.05"/></geometry><material
    name="aluminium"><color rgba="0.8 0.8 0.8 1"/></material></visual><visual><origin
    rpy="0 0 0" xyz="0 0 -0.2"/><geometry><cylinder length="0.4" radius="0.03"/></geometry><material
    name="aluminium"><color rgba="0.8 0.8 0.8 1"/></material></visual><collision><origin
    rpy="0 0 0" xyz="0 0 0.0"/><geometry><cylinder length="0.01" radius="0.1"/></geometry></collision><collision><origin
    rpy="0 0 0" xyz="0 0 -0.2"/><geometry><cylinder length="0.4" radius="0.09"/></geometry></collision><inertial><origin
    rpy="0 0 0" xyz="-0.022 0.0203 0.02917"/><mass value="0.1"/><inertia ixx="0.004878"
    ixy="-6.2341e-07" ixz="-7.4538e-07" iyy="0.00090164" iyz="-0.00014394" izz="0.0042946"/></inertial></link><joint
    name="gps_antenna_j" type="fixed"><parent link="rear_right_box"/><child link="gps_antenna"/><origin
    rpy="0 0 0" xyz="0.03 0.11 0.405"/></joint><link name="dgps_main_antenna"><visual><origin
    rpy="0 0 0" xyz="0 0 0.0415"/><geometry><cylinder length="0.083" radius="0.02"/></geometry><material
    name="black_color"><color rgba="0.0 0.0 0.0 1.0"/></material></visual><collision><origin
    rpy="0 0 0" xyz="0 0 0.0415"/><geometry><cylinder length="0.083" radius="0.02"/></geometry></collision><inertial><mass
    value="0.035"/><origin rpy="0 0 0" xyz="0 0 0.0415"/><inertia ixx="2.35929166667e-05"
    ixy="0.0" ixz="0.0" iyy="2.35929166667e-05" iyz="0.0" izz="7e-06"/></inertial></link><joint
    name="dgps_main_antenna_j" type="fixed"><parent link="rear_right_box"/><child
    link="dgps_main_antenna"/><origin rpy="0.0 0.0 0.0" xyz="0.03 0.07 0.4"/></joint><link
    name="dgps_aux_antenna"><visual><origin rpy="0 0 0" xyz="0 0 0.0415"/><geometry><cylinder
    length="0.083" radius="0.02"/></geometry><material name="black_color"><color rgba="0.0
    0.0 0.0 1.0"/></material></visual><collision><origin rpy="0 0 0" xyz="0 0 0.0415"/><geometry><cylinder
    length="0.083" radius="0.02"/></geometry></collision><inertial><mass value="0.035"/><origin
    rpy="0 0 0" xyz="0 0 0.0415"/><inertia ixx="2.35929166667e-05" ixy="0.0" ixz="0.0"
    iyy="2.35929166667e-05" iyz="0.0" izz="7e-06"/></inertial></link><joint name="dgps_aux_antenna_j"
    type="fixed"><parent link="rear_right_box"/><child link="dgps_aux_antenna"/><origin
    rpy="0.0 0.0 0.0" xyz="0.57 0.1215 0.35"/></joint><link name="left_track"><visual><origin
    rpy="1.57 0 1.57" xyz="0 0 -0.0705"/><geometry><mesh filename="package://nifti_robot_description/meshes/bogie.dae"
    scale="1.0 1.0 1.0"/></geometry></visual><collision><origin rpy="1.57079632679
    0 1.57079632679" xyz="0 0 0.01855"/><geometry><box size="0.097000 0.178 0.500000"/></geometry></collision><collision><origin
    rpy="1.57079632679 0 0" xyz="0.25 -0.015 0.01855"/><geometry><cylinder length="0.112"
    radius="0.089000"/></geometry></collision><collision><origin rpy="1.57079632679
    0 0" xyz="-0.25 0 0.01855"/><geometry><cylinder length="0.097000" radius="0.089000"/></geometry></collision><inertial><origin
    rpy="0 0 0" xyz="0 0 0.0141"/><mass value="6.06"/><inertia ixx="0.002731" ixy="0.0"
    ixz="0.0" iyy="0.032554" iyz="1.5e-05" izz="0.031391"/></inertial></link><joint
    name="left_track_j" type="revolute"><parent link="base_link"/><child link="left_track"/><axis
    xyz="0 1 0"/><origin rpy="0 0.0 0" xyz="0 0.1985 0"/><limit effort="0" lower="-0.7"
    upper="0.7" velocity="4"/></joint><link name="right_track"><visual><origin rpy="1.57
    0 -1.57" xyz="0 0 -0.0705"/><geometry><mesh filename="package://nifti_robot_description/meshes/bogie.dae"
    scale="1.0 1.0 1.0"/></geometry></visual><collision><origin rpy="1.57079632679
    0 1.57079632679" xyz="0 0 0.01855"/><geometry><box size="0.097000 0.178 0.500000"/></geometry></collision><collision><origin
    rpy="1.57079632679 0 0" xyz="0.25 0.015 0.01855"/><geometry><cylinder length="0.112"
    radius="0.089000"/></geometry></collision><collision><origin rpy="1.57079632679
    0 0" xyz="-0.25 0 0.01855"/><geometry><cylinder length="0.097000" radius="0.089000"/></geometry></collision><inertial><origin
    rpy="0 0 0" xyz="0 0 0.0141"/><mass value="6.06"/><inertia ixx="0.002731" ixy="0.0"
    ixz="0.0" iyy="0.032554" iyz="1.5e-05" izz="0.031391"/></inertial></link><joint
    name="right_track_j" type="revolute"><parent link="base_link"/><child link="right_track"/><axis
    xyz="0 1 0"/><origin rpy="0 0.0 0" xyz="0 -0.1985 0"/><mimic joint="left_track_j"
    multiplier="-1"/><limit effort="0" lower="-0.7" upper="0.7" velocity="4"/></joint><link
    name="front_left_flipper"><visual><origin rpy="3.32575 0 1.57079632679" xyz="0
    0 0"/><geometry><mesh filename="package://nifti_robot_description/meshes/flipper.dae"
    scale="1.0 1.0 1.0"/></geometry></visual><collision name="front_left_flipper_collision_large_wheel"><origin
    rpy="1.57079632679 0 0" xyz="0 -0.0 0"/><geometry><cylinder length="0.04981" radius="0.089000"/></geometry></collision><collision
    name="front_left_flipper_collision_small_wheel"><origin rpy="1.57079632679 0 0"
    xyz="0.33 -0.0 0.0"/><geometry><cylinder length="0.04981" radius="0.0435"/></geometry></collision><collision
    name="front_left_flipper_collision_top_bar"><origin rpy="0 0.184162095 0.0" xyz="0.165
    -0.0 0.0325"/><geometry><box size="0.330000 0.04981 0.0825"/></geometry></collision><collision
    name="front_left_flipper_collision_bottom_bar"><origin rpy="0 -0.184162095 0.0"
    xyz="0.165 -0.0 -0.0325"/><geometry><box size="0.330000 0.04981 0.0825"/></geometry></collision><collision
    name="front_left_flipper_collision_middle_bar"><origin rpy="0 -0.02 0.0" xyz="0.166
    -0.0 0.004"/><geometry><box size="0.20 0.04981 0.07"/></geometry></collision><inertial><origin
    rpy="0 0 0" xyz="0.08 0 0.0"/><mass value="0.75"/><inertia ixx="0.0017491" ixy="2.8512e-07"
    ixz="0.0018277" iyy="0.012277" iyz="-3.6288e-07" izz="0.010941"/></inertial><sensor
    name="front_left_flipper_contact" type="contact"><contact><collision>front_left_flipper_collision</collision><collision>front_left_flipper_collision_large_wheel</collision><collision>front_left_flipper_collision_small_wheel</collision><collision>front_left_flipper_collision_top_bar</collision><collision>front_left_flipper_collision_bottom_bar</collision><collision>front_left_flipper_collision_middle_bar</collision></contact></sensor></link><joint
    name="front_left_flipper_j" type="continuous"><parent link="left_track"/><child
    link="front_left_flipper"/><axis xyz="0 1 0"/><origin rpy="0 0.193732 0" xyz="0.25
    0.0735 0.0195"/></joint><link name="front_left_flipper_end_point"/><joint name="front_left_flipper_end_point_j"
    type="fixed"><parent link="front_left_flipper"/><child link="front_left_flipper_end_point"/><origin
    rpy="0 0.193732 0" xyz="0.3476 0 0"/></joint><link name="front_right_flipper"><visual><origin
    rpy="3.32575 0 -1.57079632679" xyz="0 0 0"/><geometry><mesh filename="package://nifti_robot_description/meshes/flipper.dae"
    scale="1.0 1.0 1.0"/></geometry></visual><collision name="front_right_flipper_collision_large_wheel"><origin
    rpy="1.57079632679 0 0" xyz="0 0.0 0"/><geometry><cylinder length="0.04981" radius="0.089000"/></geometry></collision><collision
    name="front_right_flipper_collision_small_wheel"><origin rpy="1.57079632679 0
    0" xyz="-0.33 0.0 0.0"/><geometry><cylinder length="0.04981" radius="0.0435"/></geometry></collision><collision
    name="front_right_flipper_collision_top_bar"><origin rpy="0 0.184162095 3.14159265359"
    xyz="-0.165 0.0 0.0325"/><geometry><box size="0.330000 0.04981 0.0825"/></geometry></collision><collision
    name="front_right_flipper_collision_bottom_bar"><origin rpy="0 -0.184162095 3.14159265359"
    xyz="-0.165 0.0 -0.0325"/><geometry><box size="0.330000 0.04981 0.0825"/></geometry></collision><collision
    name="front_right_flipper_collision_middle_bar"><origin rpy="0 -0.02 3.14159265359"
    xyz="-0.166 0.0 0.004"/><geometry><box size="0.20 0.04981 0.07"/></geometry></collision><inertial><origin
    rpy="0 0 0" xyz="-0.08 0 0.0"/><mass value="0.75"/><inertia ixx="0.0017491" ixy="2.8512e-07"
    ixz="0.0018277" iyy="0.012277" iyz="-3.6288e-07" izz="0.010941"/></inertial><sensor
    name="front_right_flipper_contact" type="contact"><contact><collision>front_right_flipper_collision</collision><collision>front_right_flipper_collision_large_wheel</collision><collision>front_right_flipper_collision_small_wheel</collision><collision>front_right_flipper_collision_top_bar</collision><collision>front_right_flipper_collision_bottom_bar</collision><collision>front_right_flipper_collision_middle_bar</collision></contact></sensor></link><joint
    name="front_right_flipper_j" type="continuous"><parent link="right_track"/><child
    link="front_right_flipper"/><axis xyz="0 1 0"/><origin rpy="0 -2.94786065359 0"
    xyz="0.25 -0.0735 0.0195"/></joint><link name="front_right_flipper_end_point"/><joint
    name="front_right_flipper_end_point_j" type="fixed"><parent link="front_right_flipper"/><child
    link="front_right_flipper_end_point"/><origin rpy="0 0.193732 0" xyz="-0.3476
    0 0"/></joint><link name="rear_left_flipper"><visual><origin rpy="3.32575 0 1.57079632679"
    xyz="0 0 0"/><geometry><mesh filename="package://nifti_robot_description/meshes/flipper.dae"
    scale="1.0 1.0 1.0"/></geometry></visual><collision name="rear_left_flipper_collision_large_wheel"><origin
    rpy="1.57079632679 0 0" xyz="0 -0.0 0"/><geometry><cylinder length="0.04981" radius="0.089000"/></geometry></collision><collision
    name="rear_left_flipper_collision_small_wheel"><origin rpy="1.57079632679 0 0"
    xyz="0.33 -0.0 0.0"/><geometry><cylinder length="0.04981" radius="0.029"/></geometry></collision><collision
    name="rear_left_flipper_collision_top_bar"><origin rpy="0 0.184162095 0.0" xyz="0.165
    -0.0 0.0325"/><geometry><box size="0.330000 0.04981 0.055"/></geometry></collision><collision
    name="rear_left_flipper_collision_bottom_bar"><origin rpy="0 -0.184162095 0.0"
    xyz="0.165 -0.0 -0.0325"/><geometry><box size="0.330000 0.04981 0.055"/></geometry></collision><collision
    name="rear_left_flipper_collision_middle_bar"><origin rpy="0 -0.02 0.0" xyz="0.166
    -0.0 0.004"/><geometry><box size="0.20 0.04981 0.07"/></geometry></collision><inertial><origin
    rpy="0 0 0" xyz="0.08 0 0.0"/><mass value="0.75"/><inertia ixx="0.0017491" ixy="2.8512e-07"
    ixz="0.0018277" iyy="0.012277" iyz="-3.6288e-07" izz="0.010941"/></inertial><sensor
    name="rear_left_flipper_contact" type="contact"><contact><collision>rear_left_flipper_collision</collision><collision>rear_left_flipper_collision_large_wheel</collision><collision>rear_left_flipper_collision_small_wheel</collision><collision>rear_left_flipper_collision_top_bar</collision><collision>rear_left_flipper_collision_bottom_bar</collision><collision>rear_left_flipper_collision_middle_bar</collision></contact></sensor></link><joint
    name="rear_left_flipper_j" type="continuous"><parent link="left_track"/><child
    link="rear_left_flipper"/><axis xyz="0 1 0"/><origin rpy="0 2.94786065359 0" xyz="-0.25
    0.0735 0.0195"/></joint><link name="rear_left_flipper_end_point"/><joint name="rear_left_flipper_end_point_j"
    type="fixed"><parent link="rear_left_flipper"/><child link="rear_left_flipper_end_point"/><origin
    rpy="0 0.193732 0" xyz="0.3476 0 0"/></joint><link name="rear_right_flipper"><visual><origin
    rpy="3.32575 0 -1.57079632679" xyz="0 0 0"/><geometry><mesh filename="package://nifti_robot_description/meshes/flipper.dae"
    scale="1.0 1.0 1.0"/></geometry></visual><collision name="rear_right_flipper_collision_large_wheel"><origin
    rpy="1.57079632679 0 0" xyz="0 0.0 0"/><geometry><cylinder length="0.04981" radius="0.089000"/></geometry></collision><collision
    name="rear_right_flipper_collision_small_wheel"><origin rpy="1.57079632679 0 0"
    xyz="-0.33 0.0 0.0"/><geometry><cylinder length="0.04981" radius="0.029"/></geometry></collision><collision
    name="rear_right_flipper_collision_top_bar"><origin rpy="0 0.184162095 3.14159265359"
    xyz="-0.165 0.0 0.0325"/><geometry><box size="0.330000 0.04981 0.055"/></geometry></collision><collision
    name="rear_right_flipper_collision_bottom_bar"><origin rpy="0 -0.184162095 3.14159265359"
    xyz="-0.165 0.0 -0.0325"/><geometry><box size="0.330000 0.04981 0.055"/></geometry></collision><collision
    name="rear_right_flipper_collision_middle_bar"><origin rpy="0 -0.02 3.14159265359"
    xyz="-0.166 0.0 0.004"/><geometry><box size="0.20 0.04981 0.07"/></geometry></collision><inertial><origin
    rpy="0 0 0" xyz="-0.08 0 0.0"/><mass value="0.75"/><inertia ixx="0.0017491" ixy="2.8512e-07"
    ixz="0.0018277" iyy="0.012277" iyz="-3.6288e-07" izz="0.010941"/></inertial><sensor
    name="rear_right_flipper_contact" type="contact"><contact><collision>rear_right_flipper_collision</collision><collision>rear_right_flipper_collision_large_wheel</collision><collision>rear_right_flipper_collision_small_wheel</collision><collision>rear_right_flipper_collision_top_bar</collision><collision>rear_right_flipper_collision_bottom_bar</collision><collision>rear_right_flipper_collision_middle_bar</collision></contact></sensor></link><joint
    name="rear_right_flipper_j" type="continuous"><parent link="right_track"/><child
    link="rear_right_flipper"/><axis xyz="0 1 0"/><origin rpy="0 -0.193732 0" xyz="-0.25
    -0.0735 0.0195"/></joint><link name="rear_right_flipper_end_point"/><joint name="rear_right_flipper_end_point_j"
    type="fixed"><parent link="rear_right_flipper"/><child link="rear_right_flipper_end_point"/><origin
    rpy="0 0.193732 0" xyz="-0.3476 0 0"/></joint><link name="imu"><inertial><origin
    rpy="0 0 0" xyz="0 0 0"/><mass value="1e-5"/><inertia ixx="1e-3" ixy="1e-6" ixz="1e-6"
    iyy="1e-3" iyz="1e-6" izz="1e-3"/></inertial></link><joint name="imu_j" type="fixed"><parent
    link="base_link"/><child link="imu"/><origin rpy="3.14159265359 0 -1.57079632679"
    xyz="0 0 0.1500"/></joint><link name="camera_0"><inertial><origin rpy="0 0 0"
    xyz="0 0 0"/><mass value="1e-5"/><inertia ixx="1e-3" ixy="1e-6" ixz="1e-6" iyy="1e-3"
    iyz="1e-6" izz="1e-3"/></inertial></link><link name="camera_front"><inertial><origin
    rpy="0 0 0" xyz="0 0 0"/><mass value="1e-5"/><inertia ixx="1e-3" ixy="1e-6" ixz="1e-6"
    iyy="1e-3" iyz="1e-6" izz="1e-3"/></inertial></link><joint name="camera_0_j" type="fixed"><parent
    link="rear_right_box"/><child link="camera_front"/><origin rpy="0.0 -0.0 0.0"
    xyz="0.6 0.1215 0.02"/></joint><joint name="camera_front_optical_j" type="fixed"><parent
    link="camera_front"/><child link="camera_0"/><origin rpy="-1.57079632679 0 -1.57079632679"
    xyz="0 0 0"/></joint><link name="camera_1"><inertial><origin rpy="0 0 0" xyz="0
    0 0"/><mass value="1e-5"/><inertia ixx="1e-3" ixy="1e-6" ixz="1e-6" iyy="1e-3"
    iyz="1e-6" izz="1e-3"/></inertial></link><link name="camera_right"><inertial><origin
    rpy="0 0 0" xyz="0 0 0"/><mass value="1e-5"/><inertia ixx="1e-3" ixy="1e-6" ixz="1e-6"
    iyy="1e-3" iyz="1e-6" izz="1e-3"/></inertial></link><joint name="camera_1_j" type="fixed"><parent
    link="rear_right_box"/><child link="camera_left"/><origin rpy="0.0 -0.0 1.57079632679"
    xyz="0.3 0.223 0.02"/></joint><joint name="camera_right_optical_j" type="fixed"><parent
    link="camera_right"/><child link="camera_1"/><origin rpy="-1.57079632679 0 -1.57079632679"
    xyz="0 0 0"/></joint><link name="camera_2"><inertial><origin rpy="0 0 0" xyz="0
    0 0"/><mass value="1e-5"/><inertia ixx="1e-3" ixy="1e-6" ixz="1e-6" iyy="1e-3"
    iyz="1e-6" izz="1e-3"/></inertial></link><link name="camera_rear"><inertial><origin
    rpy="0 0 0" xyz="0 0 0"/><mass value="1e-5"/><inertia ixx="1e-3" ixy="1e-6" ixz="1e-6"
    iyy="1e-3" iyz="1e-6" izz="1e-3"/></inertial></link><joint name="camera_2_j" type="fixed"><parent
    link="rear_right_box"/><child link="camera_rear"/><origin rpy="0.0 -0.0 3.14159265359"
    xyz="0.02 0.1215 0.02"/></joint><joint name="camera_rear_optical_j" type="fixed"><parent
    link="camera_rear"/><child link="camera_2"/><origin rpy="-1.57079632679 0 -1.57079632679"
    xyz="0 0 0"/></joint><link name="camera_3"><inertial><origin rpy="0 0 0" xyz="0
    0 0"/><mass value="1e-5"/><inertia ixx="1e-3" ixy="1e-6" ixz="1e-6" iyy="1e-3"
    iyz="1e-6" izz="1e-3"/></inertial></link><link name="camera_left"><inertial><origin
    rpy="0 0 0" xyz="0 0 0"/><mass value="1e-5"/><inertia ixx="1e-3" ixy="1e-6" ixz="1e-6"
    iyy="1e-3" iyz="1e-6" izz="1e-3"/></inertial></link><joint name="camera_3_j" type="fixed"><parent
    link="rear_right_box"/><child link="camera_right"/><origin rpy="0.0 -0.0 -1.57079632679"
    xyz="0.3 0.02 0.02"/></joint><joint name="camera_left_optical_j" type="fixed"><parent
    link="camera_left"/><child link="camera_3"/><origin rpy="-1.57079632679 0 -1.57079632679"
    xyz="0 0 0"/></joint><link name="camera_4"><inertial><origin rpy="0 0 0" xyz="0
    0 0"/><mass value="1e-5"/><inertia ixx="1e-3" ixy="1e-6" ixz="1e-6" iyy="1e-3"
    iyz="1e-6" izz="1e-3"/></inertial></link><link name="camera_top"><inertial><origin
    rpy="0 0 0" xyz="0 0 0"/><mass value="1e-5"/><inertia ixx="1e-3" ixy="1e-6" ixz="1e-6"
    iyy="1e-3" iyz="1e-6" izz="1e-3"/></inertial></link><joint name="camera_4_j" type="fixed"><parent
    link="rear_right_box"/><child link="camera_top"/><origin rpy="-0.0 -1.57079632679
    0.0" xyz="0.48 0.1215 0.25"/></joint><joint name="camera_top_optical_j" type="fixed"><parent
    link="camera_top"/><child link="camera_4"/><origin rpy="-1.57079632679 0 -1.57079632679"
    xyz="0 0 0"/></joint></robot>', robot_type: nifti, t265_parent_link: rear_sensor_item,
  t265_pos_x: -0.01101015, t265_pos_y: -0.00626623, t265_pos_z: 0.2895825, t265_quat_w: 0.7053355044495323,
  t265_quat_x: 0.0, t265_quat_y: 0.0, t265_quat_z: -0.7088736320127331, t265_rpy_p: 0.0,
  t265_rpy_r: 0.0, t265_rpy_y: -1.5758, top_box_ant_l_wifi_angle: 0.0, top_box_ant_l_wifi_length: 0.13,
  top_box_ant_l_wifi_y: 0.047, top_box_ant_l_wifi_z: 0.02, top_box_ant_lora_angle: 0.0,
  top_box_ant_lora_length: 0.11, top_box_ant_lora_y: -0.1, top_box_ant_lora_z: 0.08,
  top_box_ant_r_wifi_angle: 0.0, top_box_ant_r_wifi_length: 0.13, top_box_ant_r_wifi_y: -0.047,
  top_box_ant_r_wifi_z: 0.02, top_box_j_x: 0.504, velodyne_x_offset: 0.41, velodyne_yaw: -1.84}
ekf_odom:
  base_link_frame: base_link
  frequency: 20
  imu0: imu_filtered/data
  imu0_config: [false, false, false, true, true, false, false, false, false, true,
    true, true, false, false, false]
  imu0_differential: false
  imu0_nodelay: true
  imu0_queue_size: 10
  imu0_remove_gravitational_acceleration: true
  odom0: odom_2d
  odom0_config: [true, true, true, false, false, true, false, false, false, false,
    false, false, false, false, false]
  odom0_differential: true
  odom0_nodelay: true
  odom0_queue_size: 10
  odom_frame: odom
  print_diagnostics: false
  publish_tf: true
  reset_on_time_jump: true
  sensor_timeout: 0.03
  two_d_mode: false
  use_control: false
  world_frame: odom
error_recovery: {allow_hard_reset: true, allow_soft_reset: true, allow_tipover_protection: false,
  dangerous_pitch: 0.7853981633974483, dangerous_pose_ang_limit: 0.08726646259971647,
  dangerous_pose_lin_limit: 0.1, dangerous_roll: 0.6108652381980153, max_safe_pitch: 0.8726646259971648,
  max_safe_roll: 0.6981317007977318, stop_on_error: true}
flipper_postures:
- [0.0, 0.0]
- [-2.8797932657906435, 2.007128639793479]
- [-0.7853981633974483, 0.17453292519943295]
- [-0.17453292519943295, 0.7853981633974483]
- [0.6981317007977318, -0.6981317007977318]
- [-2.356194490192345, 2.356194490192345]
- [-2.0943951023931953, 2.0943951023931953]
gnss:
  septentrio:
    raw:
      activate_debug_log: false
      ant_aux1_serial_nr: Unknown
      ant_aux1_type: Unknown
      ant_serial_nr: Unknown
      ant_type: Unknown
      aux1_frame_id: dgps_aux_antenna
      configure_rx: true
      datum: Default
      device: serial:/dev/septentrio_usb2
      frame_id: dgps_main_antenna
      get_spatial_config_from_tf: true
      latency_compensation: false
      leap_seconds: 18
      lock_utm_zone: true
      multi_antenna: true
      polling_period: {pvt: 100, rest: 100}
      publish: {aimplusstatus: true, attcoveuler: true, atteuler: true, diagnostics: true,
        extsensormeas: true, gpgga: true, gpgsa: true, gpgsv: true, gprmc: true, gpsfix: true,
        gpst: true, localization: true, localization_ecef: true, measepoch: true,
        navsatfix: true, poscovcartesian: true, poscovgeodetic: true, pose: true,
        pvtcartesian: true, pvtgeodetic: true, tf: false, tf_ecef: false, twist: true,
        velcovcartesian: true, velcovgeodetic: true}
      receiver_type: gnss
      rtk_settings:
        ntrip_1: {caster: 'http://ntrip.pecny.cz', caster_port: 2101, keep_open: true,
          mountpoint: GOP60, rtk_standard: auto, send_gga: auto, tls: false, version: v2}
      serial: {baudrate: 921600, hw_flow_control: 'off'}
      use_gnss_time: false
      use_ros_axis_orientation: true
gyro_bias_remover: {initial_calibration_duration: 15, min_calibration_samples: 500,
  skip_calibration: false}
imu_filter: {constant_dt: 0.01, gain: 0.01, mag_bias_x: 0.0, mag_bias_y: 0.0, mag_bias_z: 0.0,
  orientation_stddev: 0.1, publish_tf: false, time_jump_threshold: 10.0, use_mag: false,
  zeta: 0.0}
imu_manager: {num_threads: 16}
imu_realign: {frame_id: imu_aligned, in_queue_size: 100, out_queue_size: 100}
initial_altitude: 100.0
initial_heading: 5.235987755982989
initial_lat: 0.8986162889567008
initial_lon: 0.130652862559011
inso_GyroscopeSF: '[1.0, 0, 0; 0, 1.0, 0; 0, 0, 1.0]'
inso_SamplingPeriod: 0.01
joy_node_clone_robot_14840_395761308642786285: {autorepeat_rate: 10.0, coalesce_interval: 0.033,
  deadzone: 0.1, dev: /dev/input/js_secondary}
joy_node_clone_robot_14840_8198789867000342241: {autorepeat_rate: 10.0, coalesce_interval: 0.033,
  deadzone: 0.1, dev: /dev/input/js_primary}
joy_node_clone_robot_3087_1984277275772791660: {autorepeat_rate: 10.0, coalesce_interval: 0.033,
  deadzone: 0.1, dev: /dev/input/js_primary}
joy_node_clone_robot_3087_3229454766952567392: {autorepeat_rate: 10.0, coalesce_interval: 0.033,
  deadzone: 0.1, dev: /dev/input/js_secondary}
joy_translator_clone_robot_14840_3809032043110638206: {dev: /dev/input/js_primary}
joy_translator_clone_robot_14840_4764899751129806876: {dev: /dev/input/js_secondary}
joy_translator_clone_robot_3087_4729353531170790714: {dev: /dev/input/js_secondary}
joy_translator_clone_robot_3087_6103717175222387694: {dev: /dev/input/js_primary}
laser_angle_offset: 0.0
laser_nodelet_manager: {num_worker_threads: 8}
laser_nodelet_manager_jetson: {num_worker_threads: 16}
laser_nodelet_manager_nuc: {num_worker_threads: 16}
laser_time_offset: -0.01
led_driver_board: {device: /dev/ttyUSB_led_driver}
led_driver_board_devices:
  electronic_io_devices:
    led_all:
      devices: [led_front, led_rear, led_left, led_right, led_top]
      topic: led/all
      type: electronic_io.OutputGroup
    led_all_except_top:
      devices: [led_front, led_rear, led_left, led_right]
      topic: led/all_except_top
      type: electronic_io.OutputGroup
    led_front:
      enable_pin: {pin: Output4}
      pwm_pin: {pin: RawPWM3}
      topic: led/front
      type: electronic_io.DimmableLED
    led_left:
      enable_pin: {pin: Output2}
      pwm_pin: {pin: RawPWM1}
      topic: led/left
      type: electronic_io.DimmableLED
    led_rear:
      enable_pin: {pin: Output5}
      pwm_pin: {pin: RawPWM4}
      topic: led/rear
      type: electronic_io.DimmableLED
    led_right:
      enable_pin: {pin: Output3}
      pwm_pin: {pin: RawPWM2}
      topic: led/right
      type: electronic_io.DimmableLED
    led_switch_all:
      output_pins:
      - {pin: Output8}
      topic: led/switch_all
      type: electronic_io.PowerSwitch
    led_switch_all_except_top:
      output_pins:
      - {pin: Output2}
      - {pin: Output3}
      - {pin: Output4}
      - {pin: Output5}
      topic: led/switch_all_except_top
      type: electronic_io.PowerSwitch
    led_top:
      enable_pin: {pin: Output1}
      pwm_pin: {pin: RawPWM0}
      topic: led/top
      type: electronic_io.DimmableLED
    power_distribution_voltage_12v:
      input_pin: {pin: Voltage2}
      topic: power_distribution/voltage_12v
      type: electronic_io.Voltmeter
    power_distribution_voltage_24v:
      input_pin: {pin: Voltage1}
      topic: power_distribution/voltage_24v
      type: electronic_io.Voltmeter
    power_distribution_voltage_5v:
      input_pin: {pin: Voltage3}
      topic: power_distribution/voltage_5v
      type: electronic_io.Voltmeter
    power_switch_motors:
      output_pins:
      - {pin: Output7}
      topic: power_switch/motors
      type: electronic_io.PowerSwitch
    temperature_main_pc_left:
      input_pin: {pin: Temp4}
      topic: temperature/main_pc_left
      type: electronic_io.Thermometer
    temperature_main_pc_right:
      input_pin: {pin: Temp5}
      topic: temperature/main_pc_right
      type: electronic_io.Thermometer
    temperature_nuc_left:
      input_pin: {pin: Temp2}
      topic: temperature/nuc_left
      type: electronic_io.Thermometer
    temperature_nuc_right:
      input_pin: {pin: Temp3}
      topic: temperature/nuc_right
      type: electronic_io.Thermometer
    temperature_top_box:
      input_pin: {pin: Temp1}
      topic: temperature/top_box
      type: electronic_io.Thermometer
  virtual_pins:
    pwm1:
      adc_pin: {pin: PWM1}
      linear_coeff: 0.005
      name: RawPWM1
      type: electronic_io.LinearADCPin
      unit: PWM
    pwm2:
      adc_pin: {pin: PWM2}
      linear_coeff: 0.005
      name: RawPWM2
      type: electronic_io.LinearADCPin
      unit: PWM
    pwm3:
      adc_pin: {pin: PWM3}
      linear_coeff: 0.005
      name: RawPWM3
      type: electronic_io.LinearADCPin
      unit: PWM
    pwm4:
      adc_pin: {pin: PWM4}
      linear_coeff: 0.005
      name: RawPWM4
      type: electronic_io.LinearADCPin
      unit: PWM
    pwm5:
      adc_pin: {pin: PWM0}
      linear_coeff: 0.005
      name: RawPWM0
      type: electronic_io.LinearADCPin
      unit: PWM
led_driver_node: {device: /dev/ttyUSB_led_driver}
llh_publisher: {baud: 115200, port: /dev/ttyACM_gps}
magnetometer_bias_x: 0.0979657769203186
magnetometer_bias_y: 2.047601103782654
magnetometer_bias_z: 0
mapper_node: {alpha: 0.8, backup_in_ram: false, beam_half_angle: 0.003054326, beta: 0.99,
  compute_prob_dynamic: true, epsilon_a: 0.01, epsilon_d: 0.01, icp_config: /home/robot/workspace/mapper_ws/src/ctu_mapping/params/realtime_icp_config.yaml,
  input_filters_config: /home/robot/workspace/mapper_ws/src/ctu_mapping/params/realtime_input_filters.yaml,
  map_post_filters_config: /home/robot/workspace/mapper_ws/src/ctu_mapping/params/realtime_post_filters.yaml,
  map_tf_publish_rate: 100, map_update_condition: overlap, map_update_overlap: 0.95,
  min_dist_new_point: 0.11, odom_frame: odom, prior_dynamic: 0.5, publish_tfs_between_registrations: false,
  robot_frame: base_link, save_map_cells_on_hard_drive: false, sensor_max_range: 50,
  threshold_dynamic: 0.75}
mikrotik_switch: {address: 'http://192.168.1.1/', password: nifti, username: admin}
mtig_node: {device: /dev/ttyS1, frame_id: imu, frame_local: ENU, frame_local_imu: NWU}
mux_cmd_vel: {initial_topic: __none}
mux_flipper_cmd: {initial_topic: __none}
mux_flippers_cmd: {initial_topic: __none}
mux_flippers_cmd_vel: {initial_topic: __none}
mux_laser_center: {initial_topic: __none}
mux_posture_cmd: {initial_topic: __none}
mux_posture_cmd_stamped: {initial_topic: __none}
mux_scanning_speed_cmd: {initial_topic: __none}
mux_tracks_vel_cmd: {initial_topic: __none}
nifti_diagnostic_aggregator:
  analyzers:
    cpu: {path: System Status, startswith: CPU, type: diagnostic_aggregator/GenericAnalyzer}
    darpa_estop: {find_and_remove_prefix: estop_driver, num_items: 6, path: DARPA
        E-Stop, type: diagnostic_aggregator/GenericAnalyzer}
    hdd: {path: System Status, startswith: HDD, type: diagnostic_aggregator/GenericAnalyzer}
    inso: {find_and_remove_prefix: inso, path: INSO Gyro-odometry, type: diagnostic_aggregator/GenericAnalyzer}
    joystick: {num_items: 1, path: Joystick, regex: 'joy_node_.*: Joystick Driver
        Status', type: diagnostic_aggregator/GenericAnalyzer}
    memory: {path: System Status, startswith: Memory, type: diagnostic_aggregator/GenericAnalyzer}
    network: {path: System Status, startswith: Network, type: diagnostic_aggregator/GenericAnalyzer}
    nifti_robot_node: {find_and_remove_prefix: nifti_robot_node, num_items: 8, path: Robot,
      type: diagnostic_aggregator/GenericAnalyzer}
    ntp: {path: System Status, startswith: NTP offset, type: diagnostic_aggregator/DiscardAnalyzer}
    omnicamera: {find_and_remove_prefix: viz/omnicamera_nodelet_manager, num_items: 1,
      path: Omnicamera, type: diagnostic_aggregator/GenericAnalyzer}
    sound_play: {find_and_remove_prefix: sound_play, num_items: 1, path: Vocal Feedback,
      type: diagnostic_aggregator/GenericAnalyzer}
    tf: {find_and_remove_prefix: tf_monitor, path: TF, type: diagnostic_aggregator/GenericAnalyzer}
    xsens_mtig:
      contains: [Self Test]
      path: IMU
      remove_prefix: mtnode
      type: diagnostic_aggregator/GenericAnalyzer
    xsens_mtig_ignored:
      contains: [XKF Valid, GPS Fix]
      path: IMU
      remove_prefix: mtnode
      type: diagnostic_aggregator/DiscardAnalyzer
nifti_robot_description: <?xml version="1.0" ?><robot name="NIFTi"><link name="rear_right_box"/><joint
  name="rear_right_box_j" type="fixed"><parent link="base_link"/><child link="rear_right_box"/><origin
  rpy="0 0 0" xyz="-0.3175 -0.1215 0.185"/></joint><link name="os_sensor"><visual><geometry><mesh
  filename="package://cras_ouster_description/meshes/ouster-os0.dae"/></geometry></visual><collision><origin
  rpy="0 0 0" xyz="0 0 0.03675"/><geometry><cylinder length="0.0735" radius="0.0435"/></geometry></collision><inertial><mass
  value="0.5"/><origin xyz="0 0 0.03675"/><inertia ixx="0.000461625" ixy="0.0" ixz="0.0"
  iyy="0.000461625" iyz="0.0" izz="0.0004730625"/></inertial></link><joint name="ouster_holder_j"
  type="fixed"><parent link="top_box"/><child link="ouster_holder"/><origin rpy="0.0
  0.0 0.0" xyz="0.08 0.0 0.005"/></joint><!-- workaround for https://github.com/osrf/sdformat/issues/378
  --><gazebo reference="ouster_holder_j"><preserveFixedJoint>true</preserveFixedJoint></gazebo><joint
  name="ouster_base_j" type="fixed"><parent link="ouster_holder"/><child link="ouster_base"/><origin
  rpy="0.0 0.263 0.0" xyz="-0.02 0.0 0.0"/></joint><!-- workaround for https://github.com/osrf/sdformat/issues/378
  --><gazebo reference="ouster_base_j"><preserveFixedJoint>true</preserveFixedJoint></gazebo><joint
  name="ouster_j" type="fixed"><parent link="ouster_base"/><child link="os_sensor"/><origin
  rpy="0.01 0.01 0.75" xyz="-0.0065 0.0 0.256"/></joint><!-- workaround for https://github.com/osrf/sdformat/issues/378
  --><gazebo reference="ouster_j"><preserveFixedJoint>true</preserveFixedJoint></gazebo><link
  name="ouster_base"><inertial><origin rpy="0 0 0" xyz="0 0 0"/><mass value="1e-5"/><inertia
  ixx="1e-3" ixy="1e-6" ixz="1e-6" iyy="1e-3" iyz="1e-6" izz="1e-3"/></inertial></link><link
  name="ouster_holder"><inertial><origin rpy="0 0 0" xyz="0 0 0"/><mass value="1e-5"/><inertia
  ixx="1e-3" ixy="1e-6" ixz="1e-6" iyy="1e-3" iyz="1e-6" izz="1e-3"/></inertial></link><link
  name="base_link"><visual><origin rpy="0 0 0" xyz="0 0 0"/><geometry><mesh filename="package://nifti_robot_description/meshes/body_2021.dae"
  scale="1.0 1.0 1.0"/></geometry></visual><collision><origin rpy="0 0 0" xyz="0.000000
  0 0.1395"/><geometry><box size="0.635000 0.243000 0.108"/></geometry></collision><collision><origin
  rpy="0 0 0" xyz="0 0.135 0.09"/><geometry><box size="0.055 0.040 0.08"/></geometry></collision><collision><origin
  rpy="0 0 0" xyz="0 0.155 0.013"/><geometry><box size="0.055 0.020 0.075"/></geometry></collision><collision><origin
  rpy="0 0 0" xyz="0 -0.135 0.09"/><geometry><box size="0.055 0.040 0.08"/></geometry></collision><collision><origin
  rpy="0 0 0" xyz="0 -0.155 0.013"/><geometry><box size="0.055 0.020 0.075"/></geometry></collision><collision><origin
  rpy="0 0 0" xyz="0 0 0.0655"/><geometry><box size="0.565 0.243000 0.035000"/></geometry></collision><collision><origin
  rpy="1.57079632679 0 0" xyz="0.2825 0 0.083"/><geometry><cylinder length="0.243000"
  radius="0.035035"/></geometry></collision><collision><origin rpy="1.57079632679
  0 0" xyz="-0.2825 0 0.083"/><geometry><cylinder length="0.243000" radius="0.035035"/></geometry></collision><collision
  name="big_collision_box"><origin rpy="0 0 0" xyz="0.0 0 0.255"/><geometry><box size="0.6
  0.5 0.35"/></geometry></collision><inertial><origin rpy="0 0 0" xyz="-0.034 0 0.142"/><mass
  value="6.746"/><inertia ixx="0.0069904" ixy="0.00012271" ixz="-4.2725e-05" iyy="0.02129"
  iyz="-0.00010522" izz="0.025519"/></inertial></link><link name="battery"><visual><origin
  rpy="0 0 0" xyz="0 0 0"/><geometry><mesh filename="package://nifti_robot_description/meshes/battery.dae"
  scale="1.0 1.0 1.0"/></geometry></visual><collision><origin rpy="0 0 0" xyz="0 0
  0.0410"/><geometry><box size="0.1450 0.1350 0.0820"/></geometry></collision><inertial><origin
  rpy="0 0 0" xyz="0 0 0.041"/><mass value="3.18"/><inertia ixx="0.0020793" ixy="0.0"
  ixz="0.0" iyy="0.0023127" iyz="0.0" izz="0.0032712"/></inertial></link><joint name="battery_j"
  type="fixed"><parent link="base_link"/><child link="battery"/><origin rpy="0 1.57079632679
  0" xyz="-0.105 0 0.12"/></joint><link name="battery_cover"><visual><origin xyz="0
  0 0.0335"/><geometry><box size="0.13 0.185 0.067"/></geometry><material name="body_color"><color
  rgba="0 0.36862745098 0.721568627451 1.0"/></material></visual><collision><origin
  xyz="0 0 0.0335"/><geometry><box size="0.13 0.185 0.067"/></geometry></collision></link><joint
  name="battery_cover_j" type="fixed"><parent link="rear_right_box"/><child link="battery_cover"/><origin
  rpy="0 0 0" xyz="0.225 0.1215 0.0"/></joint><link name="top_box"><visual><origin
  rpy="0 0 0" xyz="0 0 0"/><geometry><mesh filename="package://nifti_robot_description/meshes/top_box_2021_ladybug.dae"
  scale="1.0 1.0 1.0"/></geometry></visual><collision><origin rpy="0 0 0" xyz="0 0
  0.0485"/><geometry><box size="0.18 0.233 0.097"/></geometry></collision><collision><origin
  rpy="0 0 0" xyz="-0.04 0.09 0.0690"/><geometry><box size="0.0440 0.0440 0.01303"/></geometry></collision><collision><origin
  rpy="0 0 0" xyz="0.01474 -0.08352 0.07996"/><geometry><box size="0.03732 0.03523
  0.03489"/></geometry></collision><visual><origin rpy="0.0 0 0" xyz="-0.1 -0.1 0.135"/><geometry><cylinder
  length="0.11" radius="0.01"/></geometry><material name="black_color"><color rgba="0.0
  0.0 0.0 1.0"/></material></visual><collision><origin rpy="0.0 0 0" xyz="-0.1 -0.1
  0.135"/><geometry><cylinder length="0.11" radius="0.01"/></geometry></collision><visual><origin
  rpy="0.0 0 0" xyz="0.1 0.047 0.085"/><geometry><cylinder length="0.13" radius="0.01"/></geometry><material
  name="black_color"><color rgba="0.0 0.0 0.0 1.0"/></material></visual><collision><origin
  rpy="0.0 0 0" xyz="0.1 0.047 0.085"/><geometry><cylinder length="0.13" radius="0.01"/></geometry></collision><visual><origin
  rpy="0.0 0 0" xyz="0.1 -0.047 0.085"/><geometry><cylinder length="0.13" radius="0.01"/></geometry><material
  name="black_color"><color rgba="0.0 0.0 0.0 1.0"/></material></visual><collision><origin
  rpy="0.0 0 0" xyz="0.1 -0.047 0.085"/><geometry><cylinder length="0.13" radius="0.01"/></geometry></collision><inertial><origin
  rpy="0 0 0" xyz="0 0 0.041"/><mass value="0.24"/><inertia ixx="0.0026136" ixy="0.0"
  ixz="0.0" iyy="0.0049426" iyz="0.0" izz="0.0070334"/></inertial></link><joint name="top_box_j"
  type="fixed"><parent link="rear_right_box"/><child link="top_box"/><origin rpy="0
  0 0" xyz="0.414 0.1215 0.0"/></joint><link name="top_box_step"><visual><origin rpy="0
  0 0" xyz="0 0 0.05"/><geometry><box size="0.1270 0.12 0.1"/></geometry><material
  name="body_color"><color rgba="0 0.36862745098 0.721568627451 1.0"/></material></visual><visual><origin
  rpy="0 0.01 0" xyz="-0.0165 0 0.181"/><geometry><cylinder length="0.05" radius="0.025"/></geometry><material
  name="body_color"><color rgba="0 0.36862745098 0.721568627451 1.0"/></material></visual><collision><origin
  rpy="0 0 0" xyz="0 0 0.05"/><geometry><box size="0.1270 0.12 0.1"/></geometry></collision><inertial><mass
  value="1.0"/><origin xyz="0 0 0.05"/><inertia ixx="0.00217741666667" ixy="0.0" ixz="0.0"
  iyy="0.00254408333333" iyz="0.0" izz="0.00203333333333"/></inertial></link><joint
  name="top_box_step_j" type="fixed"><parent link="top_box"/><child link="top_box_step"/><origin
  rpy="0 0 0" xyz="0 0 0.06252"/></joint><link name="antenna"><visual><origin rpy="0
  0 0" xyz="0 0 0"/><geometry><mesh filename="package://nifti_robot_description/meshes/antenna.dae"
  scale="1.0 1.0 1.0"/></geometry></visual><collision><origin rpy="0 1.57079632679
  0" xyz="-0.01864 0 0"/><geometry><cylinder length="0.03718" radius="0.008"/></geometry></collision><collision><origin
  rpy="0 0 0" xyz="-0.030 0 0.19053"/><geometry><cylinder length="0.38107" radius="0.008"/></geometry></collision><inertial><origin
  rpy="0 0 0" xyz="-0.022 0.0203 0.02917"/><mass value="0.56"/><inertia ixx="0.004878"
  ixy="-6.2341e-07" ixz="-7.4538e-07" iyy="0.00090164" iyz="-0.00014394" izz="0.0042946"/></inertial></link><joint
  name="antenna_j" type="fixed"><parent link="base_link"/><child link="antenna"/><origin
  rpy="0 0 0" xyz="-0.1975 0.1 0.1551"/></joint><link name="gps_antenna"><visual><origin
  rpy="0 0 0" xyz="0 0 0.0"/><geometry><cylinder length="0.01" radius="0.05"/></geometry><material
  name="aluminium"><color rgba="0.8 0.8 0.8 1"/></material></visual><visual><origin
  rpy="0 0 0" xyz="0 0 -0.2"/><geometry><cylinder length="0.4" radius="0.03"/></geometry><material
  name="aluminium"><color rgba="0.8 0.8 0.8 1"/></material></visual><collision><origin
  rpy="0 0 0" xyz="0 0 0.0"/><geometry><cylinder length="0.01" radius="0.1"/></geometry></collision><collision><origin
  rpy="0 0 0" xyz="0 0 -0.2"/><geometry><cylinder length="0.4" radius="0.09"/></geometry></collision><inertial><origin
  rpy="0 0 0" xyz="-0.022 0.0203 0.02917"/><mass value="0.1"/><inertia ixx="0.004878"
  ixy="-6.2341e-07" ixz="-7.4538e-07" iyy="0.00090164" iyz="-0.00014394" izz="0.0042946"/></inertial></link><joint
  name="gps_antenna_j" type="fixed"><parent link="rear_right_box"/><child link="gps_antenna"/><origin
  rpy="0 0 0" xyz="0.03 0.11 0.405"/></joint><link name="dgps_main_antenna"><visual><origin
  rpy="0 0 0" xyz="0 0 0.0415"/><geometry><cylinder length="0.083" radius="0.02"/></geometry><material
  name="black_color"><color rgba="0.0 0.0 0.0 1.0"/></material></visual><collision><origin
  rpy="0 0 0" xyz="0 0 0.0415"/><geometry><cylinder length="0.083" radius="0.02"/></geometry></collision><inertial><mass
  value="0.035"/><origin rpy="0 0 0" xyz="0 0 0.0415"/><inertia ixx="2.35929166667e-05"
  ixy="0.0" ixz="0.0" iyy="2.35929166667e-05" iyz="0.0" izz="7e-06"/></inertial></link><joint
  name="dgps_main_antenna_j" type="fixed"><parent link="rear_right_box"/><child link="dgps_main_antenna"/><origin
  rpy="0.0 0.0 0.0" xyz="0.03 0.07 0.4"/></joint><link name="dgps_aux_antenna"><visual><origin
  rpy="0 0 0" xyz="0 0 0.0415"/><geometry><cylinder length="0.083" radius="0.02"/></geometry><material
  name="black_color"><color rgba="0.0 0.0 0.0 1.0"/></material></visual><collision><origin
  rpy="0 0 0" xyz="0 0 0.0415"/><geometry><cylinder length="0.083" radius="0.02"/></geometry></collision><inertial><mass
  value="0.035"/><origin rpy="0 0 0" xyz="0 0 0.0415"/><inertia ixx="2.35929166667e-05"
  ixy="0.0" ixz="0.0" iyy="2.35929166667e-05" iyz="0.0" izz="7e-06"/></inertial></link><joint
  name="dgps_aux_antenna_j" type="fixed"><parent link="rear_right_box"/><child link="dgps_aux_antenna"/><origin
  rpy="0.0 0.0 0.0" xyz="0.57 0.1215 0.35"/></joint><link name="left_track"><visual><origin
  rpy="1.57 0 1.57" xyz="0 0 -0.0705"/><geometry><mesh filename="package://nifti_robot_description/meshes/bogie.dae"
  scale="1.0 1.0 1.0"/></geometry></visual><collision><origin rpy="1.57079632679 0
  1.57079632679" xyz="0 0 0.01855"/><geometry><box size="0.097000 0.178 0.500000"/></geometry></collision><collision><origin
  rpy="1.57079632679 0 0" xyz="0.25 -0.015 0.01855"/><geometry><cylinder length="0.112"
  radius="0.089000"/></geometry></collision><collision><origin rpy="1.57079632679
  0 0" xyz="-0.25 0 0.01855"/><geometry><cylinder length="0.097000" radius="0.089000"/></geometry></collision><inertial><origin
  rpy="0 0 0" xyz="0 0 0.0141"/><mass value="6.06"/><inertia ixx="0.002731" ixy="0.0"
  ixz="0.0" iyy="0.032554" iyz="1.5e-05" izz="0.031391"/></inertial></link><joint
  name="left_track_j" type="revolute"><parent link="base_link"/><child link="left_track"/><axis
  xyz="0 1 0"/><origin rpy="0 0.0 0" xyz="0 0.1985 0"/><limit effort="0" lower="-0.7"
  upper="0.7" velocity="4"/></joint><link name="right_track"><visual><origin rpy="1.57
  0 -1.57" xyz="0 0 -0.0705"/><geometry><mesh filename="package://nifti_robot_description/meshes/bogie.dae"
  scale="1.0 1.0 1.0"/></geometry></visual><collision><origin rpy="1.57079632679 0
  1.57079632679" xyz="0 0 0.01855"/><geometry><box size="0.097000 0.178 0.500000"/></geometry></collision><collision><origin
  rpy="1.57079632679 0 0" xyz="0.25 0.015 0.01855"/><geometry><cylinder length="0.112"
  radius="0.089000"/></geometry></collision><collision><origin rpy="1.57079632679
  0 0" xyz="-0.25 0 0.01855"/><geometry><cylinder length="0.097000" radius="0.089000"/></geometry></collision><inertial><origin
  rpy="0 0 0" xyz="0 0 0.0141"/><mass value="6.06"/><inertia ixx="0.002731" ixy="0.0"
  ixz="0.0" iyy="0.032554" iyz="1.5e-05" izz="0.031391"/></inertial></link><joint
  name="right_track_j" type="revolute"><parent link="base_link"/><child link="right_track"/><axis
  xyz="0 1 0"/><origin rpy="0 0.0 0" xyz="0 -0.1985 0"/><mimic joint="left_track_j"
  multiplier="-1"/><limit effort="0" lower="-0.7" upper="0.7" velocity="4"/></joint><link
  name="front_left_flipper"><visual><origin rpy="3.32575 0 1.57079632679" xyz="0 0
  0"/><geometry><mesh filename="package://nifti_robot_description/meshes/flipper.dae"
  scale="1.0 1.0 1.0"/></geometry></visual><collision name="front_left_flipper_collision_large_wheel"><origin
  rpy="1.57079632679 0 0" xyz="0 -0.0 0"/><geometry><cylinder length="0.04981" radius="0.089000"/></geometry></collision><collision
  name="front_left_flipper_collision_small_wheel"><origin rpy="1.57079632679 0 0"
  xyz="0.33 -0.0 0.0"/><geometry><cylinder length="0.04981" radius="0.0435"/></geometry></collision><collision
  name="front_left_flipper_collision_top_bar"><origin rpy="0 0.184162095 0.0" xyz="0.165
  -0.0 0.0325"/><geometry><box size="0.330000 0.04981 0.0825"/></geometry></collision><collision
  name="front_left_flipper_collision_bottom_bar"><origin rpy="0 -0.184162095 0.0"
  xyz="0.165 -0.0 -0.0325"/><geometry><box size="0.330000 0.04981 0.0825"/></geometry></collision><collision
  name="front_left_flipper_collision_middle_bar"><origin rpy="0 -0.02 0.0" xyz="0.166
  -0.0 0.004"/><geometry><box size="0.20 0.04981 0.07"/></geometry></collision><inertial><origin
  rpy="0 0 0" xyz="0.08 0 0.0"/><mass value="0.75"/><inertia ixx="0.0017491" ixy="2.8512e-07"
  ixz="0.0018277" iyy="0.012277" iyz="-3.6288e-07" izz="0.010941"/></inertial><sensor
  name="front_left_flipper_contact" type="contact"><contact><collision>front_left_flipper_collision</collision><collision>front_left_flipper_collision_large_wheel</collision><collision>front_left_flipper_collision_small_wheel</collision><collision>front_left_flipper_collision_top_bar</collision><collision>front_left_flipper_collision_bottom_bar</collision><collision>front_left_flipper_collision_middle_bar</collision></contact></sensor></link><joint
  name="front_left_flipper_j" type="continuous"><parent link="left_track"/><child
  link="front_left_flipper"/><axis xyz="0 1 0"/><origin rpy="0 0.193732 0" xyz="0.25
  0.0735 0.0195"/></joint><link name="front_left_flipper_end_point"/><joint name="front_left_flipper_end_point_j"
  type="fixed"><parent link="front_left_flipper"/><child link="front_left_flipper_end_point"/><origin
  rpy="0 0.193732 0" xyz="0.3476 0 0"/></joint><link name="front_right_flipper"><visual><origin
  rpy="3.32575 0 -1.57079632679" xyz="0 0 0"/><geometry><mesh filename="package://nifti_robot_description/meshes/flipper.dae"
  scale="1.0 1.0 1.0"/></geometry></visual><collision name="front_right_flipper_collision_large_wheel"><origin
  rpy="1.57079632679 0 0" xyz="0 0.0 0"/><geometry><cylinder length="0.04981" radius="0.089000"/></geometry></collision><collision
  name="front_right_flipper_collision_small_wheel"><origin rpy="1.57079632679 0 0"
  xyz="-0.33 0.0 0.0"/><geometry><cylinder length="0.04981" radius="0.0435"/></geometry></collision><collision
  name="front_right_flipper_collision_top_bar"><origin rpy="0 0.184162095 3.14159265359"
  xyz="-0.165 0.0 0.0325"/><geometry><box size="0.330000 0.04981 0.0825"/></geometry></collision><collision
  name="front_right_flipper_collision_bottom_bar"><origin rpy="0 -0.184162095 3.14159265359"
  xyz="-0.165 0.0 -0.0325"/><geometry><box size="0.330000 0.04981 0.0825"/></geometry></collision><collision
  name="front_right_flipper_collision_middle_bar"><origin rpy="0 -0.02 3.14159265359"
  xyz="-0.166 0.0 0.004"/><geometry><box size="0.20 0.04981 0.07"/></geometry></collision><inertial><origin
  rpy="0 0 0" xyz="-0.08 0 0.0"/><mass value="0.75"/><inertia ixx="0.0017491" ixy="2.8512e-07"
  ixz="0.0018277" iyy="0.012277" iyz="-3.6288e-07" izz="0.010941"/></inertial><sensor
  name="front_right_flipper_contact" type="contact"><contact><collision>front_right_flipper_collision</collision><collision>front_right_flipper_collision_large_wheel</collision><collision>front_right_flipper_collision_small_wheel</collision><collision>front_right_flipper_collision_top_bar</collision><collision>front_right_flipper_collision_bottom_bar</collision><collision>front_right_flipper_collision_middle_bar</collision></contact></sensor></link><joint
  name="front_right_flipper_j" type="continuous"><parent link="right_track"/><child
  link="front_right_flipper"/><axis xyz="0 1 0"/><origin rpy="0 -2.94786065359 0"
  xyz="0.25 -0.0735 0.0195"/></joint><link name="front_right_flipper_end_point"/><joint
  name="front_right_flipper_end_point_j" type="fixed"><parent link="front_right_flipper"/><child
  link="front_right_flipper_end_point"/><origin rpy="0 0.193732 0" xyz="-0.3476 0
  0"/></joint><link name="rear_left_flipper"><visual><origin rpy="3.32575 0 1.57079632679"
  xyz="0 0 0"/><geometry><mesh filename="package://nifti_robot_description/meshes/flipper.dae"
  scale="1.0 1.0 1.0"/></geometry></visual><collision name="rear_left_flipper_collision_large_wheel"><origin
  rpy="1.57079632679 0 0" xyz="0 -0.0 0"/><geometry><cylinder length="0.04981" radius="0.089000"/></geometry></collision><collision
  name="rear_left_flipper_collision_small_wheel"><origin rpy="1.57079632679 0 0" xyz="0.33
  -0.0 0.0"/><geometry><cylinder length="0.04981" radius="0.029"/></geometry></collision><collision
  name="rear_left_flipper_collision_top_bar"><origin rpy="0 0.184162095 0.0" xyz="0.165
  -0.0 0.0325"/><geometry><box size="0.330000 0.04981 0.055"/></geometry></collision><collision
  name="rear_left_flipper_collision_bottom_bar"><origin rpy="0 -0.184162095 0.0" xyz="0.165
  -0.0 -0.0325"/><geometry><box size="0.330000 0.04981 0.055"/></geometry></collision><collision
  name="rear_left_flipper_collision_middle_bar"><origin rpy="0 -0.02 0.0" xyz="0.166
  -0.0 0.004"/><geometry><box size="0.20 0.04981 0.07"/></geometry></collision><inertial><origin
  rpy="0 0 0" xyz="0.08 0 0.0"/><mass value="0.75"/><inertia ixx="0.0017491" ixy="2.8512e-07"
  ixz="0.0018277" iyy="0.012277" iyz="-3.6288e-07" izz="0.010941"/></inertial><sensor
  name="rear_left_flipper_contact" type="contact"><contact><collision>rear_left_flipper_collision</collision><collision>rear_left_flipper_collision_large_wheel</collision><collision>rear_left_flipper_collision_small_wheel</collision><collision>rear_left_flipper_collision_top_bar</collision><collision>rear_left_flipper_collision_bottom_bar</collision><collision>rear_left_flipper_collision_middle_bar</collision></contact></sensor></link><joint
  name="rear_left_flipper_j" type="continuous"><parent link="left_track"/><child link="rear_left_flipper"/><axis
  xyz="0 1 0"/><origin rpy="0 2.94786065359 0" xyz="-0.25 0.0735 0.0195"/></joint><link
  name="rear_left_flipper_end_point"/><joint name="rear_left_flipper_end_point_j"
  type="fixed"><parent link="rear_left_flipper"/><child link="rear_left_flipper_end_point"/><origin
  rpy="0 0.193732 0" xyz="0.3476 0 0"/></joint><link name="rear_right_flipper"><visual><origin
  rpy="3.32575 0 -1.57079632679" xyz="0 0 0"/><geometry><mesh filename="package://nifti_robot_description/meshes/flipper.dae"
  scale="1.0 1.0 1.0"/></geometry></visual><collision name="rear_right_flipper_collision_large_wheel"><origin
  rpy="1.57079632679 0 0" xyz="0 0.0 0"/><geometry><cylinder length="0.04981" radius="0.089000"/></geometry></collision><collision
  name="rear_right_flipper_collision_small_wheel"><origin rpy="1.57079632679 0 0"
  xyz="-0.33 0.0 0.0"/><geometry><cylinder length="0.04981" radius="0.029"/></geometry></collision><collision
  name="rear_right_flipper_collision_top_bar"><origin rpy="0 0.184162095 3.14159265359"
  xyz="-0.165 0.0 0.0325"/><geometry><box size="0.330000 0.04981 0.055"/></geometry></collision><collision
  name="rear_right_flipper_collision_bottom_bar"><origin rpy="0 -0.184162095 3.14159265359"
  xyz="-0.165 0.0 -0.0325"/><geometry><box size="0.330000 0.04981 0.055"/></geometry></collision><collision
  name="rear_right_flipper_collision_middle_bar"><origin rpy="0 -0.02 3.14159265359"
  xyz="-0.166 0.0 0.004"/><geometry><box size="0.20 0.04981 0.07"/></geometry></collision><inertial><origin
  rpy="0 0 0" xyz="-0.08 0 0.0"/><mass value="0.75"/><inertia ixx="0.0017491" ixy="2.8512e-07"
  ixz="0.0018277" iyy="0.012277" iyz="-3.6288e-07" izz="0.010941"/></inertial><sensor
  name="rear_right_flipper_contact" type="contact"><contact><collision>rear_right_flipper_collision</collision><collision>rear_right_flipper_collision_large_wheel</collision><collision>rear_right_flipper_collision_small_wheel</collision><collision>rear_right_flipper_collision_top_bar</collision><collision>rear_right_flipper_collision_bottom_bar</collision><collision>rear_right_flipper_collision_middle_bar</collision></contact></sensor></link><joint
  name="rear_right_flipper_j" type="continuous"><parent link="right_track"/><child
  link="rear_right_flipper"/><axis xyz="0 1 0"/><origin rpy="0 -0.193732 0" xyz="-0.25
  -0.0735 0.0195"/></joint><link name="rear_right_flipper_end_point"/><joint name="rear_right_flipper_end_point_j"
  type="fixed"><parent link="rear_right_flipper"/><child link="rear_right_flipper_end_point"/><origin
  rpy="0 0.193732 0" xyz="-0.3476 0 0"/></joint><link name="imu"><inertial><origin
  rpy="0 0 0" xyz="0 0 0"/><mass value="1e-5"/><inertia ixx="1e-3" ixy="1e-6" ixz="1e-6"
  iyy="1e-3" iyz="1e-6" izz="1e-3"/></inertial></link><joint name="imu_j" type="fixed"><parent
  link="base_link"/><child link="imu"/><origin rpy="3.14159265359 0 -1.57079632679"
  xyz="0 0 0.1500"/></joint><link name="camera_0"><inertial><origin rpy="0 0 0" xyz="0
  0 0"/><mass value="1e-5"/><inertia ixx="1e-3" ixy="1e-6" ixz="1e-6" iyy="1e-3" iyz="1e-6"
  izz="1e-3"/></inertial></link><link name="camera_front"><inertial><origin rpy="0
  0 0" xyz="0 0 0"/><mass value="1e-5"/><inertia ixx="1e-3" ixy="1e-6" ixz="1e-6"
  iyy="1e-3" iyz="1e-6" izz="1e-3"/></inertial></link><joint name="camera_0_j" type="fixed"><parent
  link="rear_right_box"/><child link="camera_front"/><origin rpy="0.0 -0.0 0.0" xyz="0.6
  0.1215 0.02"/></joint><joint name="camera_front_optical_j" type="fixed"><parent
  link="camera_front"/><child link="camera_0"/><origin rpy="-1.57079632679 0 -1.57079632679"
  xyz="0 0 0"/></joint><link name="camera_1"><inertial><origin rpy="0 0 0" xyz="0
  0 0"/><mass value="1e-5"/><inertia ixx="1e-3" ixy="1e-6" ixz="1e-6" iyy="1e-3" iyz="1e-6"
  izz="1e-3"/></inertial></link><link name="camera_right"><inertial><origin rpy="0
  0 0" xyz="0 0 0"/><mass value="1e-5"/><inertia ixx="1e-3" ixy="1e-6" ixz="1e-6"
  iyy="1e-3" iyz="1e-6" izz="1e-3"/></inertial></link><joint name="camera_1_j" type="fixed"><parent
  link="rear_right_box"/><child link="camera_left"/><origin rpy="0.0 -0.0 1.57079632679"
  xyz="0.3 0.223 0.02"/></joint><joint name="camera_right_optical_j" type="fixed"><parent
  link="camera_right"/><child link="camera_1"/><origin rpy="-1.57079632679 0 -1.57079632679"
  xyz="0 0 0"/></joint><link name="camera_2"><inertial><origin rpy="0 0 0" xyz="0
  0 0"/><mass value="1e-5"/><inertia ixx="1e-3" ixy="1e-6" ixz="1e-6" iyy="1e-3" iyz="1e-6"
  izz="1e-3"/></inertial></link><link name="camera_rear"><inertial><origin rpy="0
  0 0" xyz="0 0 0"/><mass value="1e-5"/><inertia ixx="1e-3" ixy="1e-6" ixz="1e-6"
  iyy="1e-3" iyz="1e-6" izz="1e-3"/></inertial></link><joint name="camera_2_j" type="fixed"><parent
  link="rear_right_box"/><child link="camera_rear"/><origin rpy="0.0 -0.0 3.14159265359"
  xyz="0.02 0.1215 0.02"/></joint><joint name="camera_rear_optical_j" type="fixed"><parent
  link="camera_rear"/><child link="camera_2"/><origin rpy="-1.57079632679 0 -1.57079632679"
  xyz="0 0 0"/></joint><link name="camera_3"><inertial><origin rpy="0 0 0" xyz="0
  0 0"/><mass value="1e-5"/><inertia ixx="1e-3" ixy="1e-6" ixz="1e-6" iyy="1e-3" iyz="1e-6"
  izz="1e-3"/></inertial></link><link name="camera_left"><inertial><origin rpy="0
  0 0" xyz="0 0 0"/><mass value="1e-5"/><inertia ixx="1e-3" ixy="1e-6" ixz="1e-6"
  iyy="1e-3" iyz="1e-6" izz="1e-3"/></inertial></link><joint name="camera_3_j" type="fixed"><parent
  link="rear_right_box"/><child link="camera_right"/><origin rpy="0.0 -0.0 -1.57079632679"
  xyz="0.3 0.02 0.02"/></joint><joint name="camera_left_optical_j" type="fixed"><parent
  link="camera_left"/><child link="camera_3"/><origin rpy="-1.57079632679 0 -1.57079632679"
  xyz="0 0 0"/></joint><link name="camera_4"><inertial><origin rpy="0 0 0" xyz="0
  0 0"/><mass value="1e-5"/><inertia ixx="1e-3" ixy="1e-6" ixz="1e-6" iyy="1e-3" iyz="1e-6"
  izz="1e-3"/></inertial></link><link name="camera_top"><inertial><origin rpy="0 0
  0" xyz="0 0 0"/><mass value="1e-5"/><inertia ixx="1e-3" ixy="1e-6" ixz="1e-6" iyy="1e-3"
  iyz="1e-6" izz="1e-3"/></inertial></link><joint name="camera_4_j" type="fixed"><parent
  link="rear_right_box"/><child link="camera_top"/><origin rpy="-0.0 -1.57079632679
  0.0" xyz="0.48 0.1215 0.25"/></joint><joint name="camera_top_optical_j" type="fixed"><parent
  link="camera_top"/><child link="camera_4"/><origin rpy="-1.57079632679 0 -1.57079632679"
  xyz="0 0 0"/></joint></robot>
nifti_robot_node: {CAN_device: /dev/usb/cpc_usb_robot, initial_current_limit: 4.0}
nifti_tf_publisher: {robot_description: '<?xml version="1.0" ?><robot name="NIFTi"><link
    name="rear_right_box"/><joint name="rear_right_box_j" type="fixed"><parent link="base_link"/><child
    link="rear_right_box"/><origin rpy="0 0 0" xyz="-0.3175 -0.1215 0.185"/></joint><link
    name="os_sensor"><visual><geometry><mesh filename="package://cras_ouster_description/meshes/ouster-os0.dae"/></geometry></visual><collision><origin
    rpy="0 0 0" xyz="0 0 0.03675"/><geometry><cylinder length="0.0735" radius="0.0435"/></geometry></collision><inertial><mass
    value="0.5"/><origin xyz="0 0 0.03675"/><inertia ixx="0.000461625" ixy="0.0" ixz="0.0"
    iyy="0.000461625" iyz="0.0" izz="0.0004730625"/></inertial></link><joint name="ouster_holder_j"
    type="fixed"><parent link="top_box"/><child link="ouster_holder"/><origin rpy="0.0
    0.0 0.0" xyz="0.08 0.0 0.005"/></joint><!-- workaround for https://github.com/osrf/sdformat/issues/378
    --><gazebo reference="ouster_holder_j"><preserveFixedJoint>true</preserveFixedJoint></gazebo><joint
    name="ouster_base_j" type="fixed"><parent link="ouster_holder"/><child link="ouster_base"/><origin
    rpy="0.0 0.263 0.0" xyz="-0.02 0.0 0.0"/></joint><!-- workaround for https://github.com/osrf/sdformat/issues/378
    --><gazebo reference="ouster_base_j"><preserveFixedJoint>true</preserveFixedJoint></gazebo><joint
    name="ouster_j" type="fixed"><parent link="ouster_base"/><child link="os_sensor"/><origin
    rpy="0.01 0.01 0.75" xyz="-0.0065 0.0 0.256"/></joint><!-- workaround for https://github.com/osrf/sdformat/issues/378
    --><gazebo reference="ouster_j"><preserveFixedJoint>true</preserveFixedJoint></gazebo><link
    name="ouster_base"><inertial><origin rpy="0 0 0" xyz="0 0 0"/><mass value="1e-5"/><inertia
    ixx="1e-3" ixy="1e-6" ixz="1e-6" iyy="1e-3" iyz="1e-6" izz="1e-3"/></inertial></link><link
    name="ouster_holder"><inertial><origin rpy="0 0 0" xyz="0 0 0"/><mass value="1e-5"/><inertia
    ixx="1e-3" ixy="1e-6" ixz="1e-6" iyy="1e-3" iyz="1e-6" izz="1e-3"/></inertial></link><link
    name="base_link"><visual><origin rpy="0 0 0" xyz="0 0 0"/><geometry><mesh filename="package://nifti_robot_description/meshes/body_2021.dae"
    scale="1.0 1.0 1.0"/></geometry></visual><collision><origin rpy="0 0 0" xyz="0.000000
    0 0.1395"/><geometry><box size="0.635000 0.243000 0.108"/></geometry></collision><collision><origin
    rpy="0 0 0" xyz="0 0.135 0.09"/><geometry><box size="0.055 0.040 0.08"/></geometry></collision><collision><origin
    rpy="0 0 0" xyz="0 0.155 0.013"/><geometry><box size="0.055 0.020 0.075"/></geometry></collision><collision><origin
    rpy="0 0 0" xyz="0 -0.135 0.09"/><geometry><box size="0.055 0.040 0.08"/></geometry></collision><collision><origin
    rpy="0 0 0" xyz="0 -0.155 0.013"/><geometry><box size="0.055 0.020 0.075"/></geometry></collision><collision><origin
    rpy="0 0 0" xyz="0 0 0.0655"/><geometry><box size="0.565 0.243000 0.035000"/></geometry></collision><collision><origin
    rpy="1.57079632679 0 0" xyz="0.2825 0 0.083"/><geometry><cylinder length="0.243000"
    radius="0.035035"/></geometry></collision><collision><origin rpy="1.57079632679
    0 0" xyz="-0.2825 0 0.083"/><geometry><cylinder length="0.243000" radius="0.035035"/></geometry></collision><collision
    name="big_collision_box"><origin rpy="0 0 0" xyz="0.0 0 0.255"/><geometry><box
    size="0.6 0.5 0.35"/></geometry></collision><inertial><origin rpy="0 0 0" xyz="-0.034
    0 0.142"/><mass value="6.746"/><inertia ixx="0.0069904" ixy="0.00012271" ixz="-4.2725e-05"
    iyy="0.02129" iyz="-0.00010522" izz="0.025519"/></inertial></link><link name="battery"><visual><origin
    rpy="0 0 0" xyz="0 0 0"/><geometry><mesh filename="package://nifti_robot_description/meshes/battery.dae"
    scale="1.0 1.0 1.0"/></geometry></visual><collision><origin rpy="0 0 0" xyz="0
    0 0.0410"/><geometry><box size="0.1450 0.1350 0.0820"/></geometry></collision><inertial><origin
    rpy="0 0 0" xyz="0 0 0.041"/><mass value="3.18"/><inertia ixx="0.0020793" ixy="0.0"
    ixz="0.0" iyy="0.0023127" iyz="0.0" izz="0.0032712"/></inertial></link><joint
    name="battery_j" type="fixed"><parent link="base_link"/><child link="battery"/><origin
    rpy="0 1.57079632679 0" xyz="-0.105 0 0.12"/></joint><link name="battery_cover"><visual><origin
    xyz="0 0 0.0335"/><geometry><box size="0.13 0.185 0.067"/></geometry><material
    name="body_color"><color rgba="0 0.36862745098 0.721568627451 1.0"/></material></visual><collision><origin
    xyz="0 0 0.0335"/><geometry><box size="0.13 0.185 0.067"/></geometry></collision></link><joint
    name="battery_cover_j" type="fixed"><parent link="rear_right_box"/><child link="battery_cover"/><origin
    rpy="0 0 0" xyz="0.225 0.1215 0.0"/></joint><link name="top_box"><visual><origin
    rpy="0 0 0" xyz="0 0 0"/><geometry><mesh filename="package://nifti_robot_description/meshes/top_box_2021_ladybug.dae"
    scale="1.0 1.0 1.0"/></geometry></visual><collision><origin rpy="0 0 0" xyz="0
    0 0.0485"/><geometry><box size="0.18 0.233 0.097"/></geometry></collision><collision><origin
    rpy="0 0 0" xyz="-0.04 0.09 0.0690"/><geometry><box size="0.0440 0.0440 0.01303"/></geometry></collision><collision><origin
    rpy="0 0 0" xyz="0.01474 -0.08352 0.07996"/><geometry><box size="0.03732 0.03523
    0.03489"/></geometry></collision><visual><origin rpy="0.0 0 0" xyz="-0.1 -0.1
    0.135"/><geometry><cylinder length="0.11" radius="0.01"/></geometry><material
    name="black_color"><color rgba="0.0 0.0 0.0 1.0"/></material></visual><collision><origin
    rpy="0.0 0 0" xyz="-0.1 -0.1 0.135"/><geometry><cylinder length="0.11" radius="0.01"/></geometry></collision><visual><origin
    rpy="0.0 0 0" xyz="0.1 0.047 0.085"/><geometry><cylinder length="0.13" radius="0.01"/></geometry><material
    name="black_color"><color rgba="0.0 0.0 0.0 1.0"/></material></visual><collision><origin
    rpy="0.0 0 0" xyz="0.1 0.047 0.085"/><geometry><cylinder length="0.13" radius="0.01"/></geometry></collision><visual><origin
    rpy="0.0 0 0" xyz="0.1 -0.047 0.085"/><geometry><cylinder length="0.13" radius="0.01"/></geometry><material
    name="black_color"><color rgba="0.0 0.0 0.0 1.0"/></material></visual><collision><origin
    rpy="0.0 0 0" xyz="0.1 -0.047 0.085"/><geometry><cylinder length="0.13" radius="0.01"/></geometry></collision><inertial><origin
    rpy="0 0 0" xyz="0 0 0.041"/><mass value="0.24"/><inertia ixx="0.0026136" ixy="0.0"
    ixz="0.0" iyy="0.0049426" iyz="0.0" izz="0.0070334"/></inertial></link><joint
    name="top_box_j" type="fixed"><parent link="rear_right_box"/><child link="top_box"/><origin
    rpy="0 0 0" xyz="0.414 0.1215 0.0"/></joint><link name="top_box_step"><visual><origin
    rpy="0 0 0" xyz="0 0 0.05"/><geometry><box size="0.1270 0.12 0.1"/></geometry><material
    name="body_color"><color rgba="0 0.36862745098 0.721568627451 1.0"/></material></visual><visual><origin
    rpy="0 0.01 0" xyz="-0.0165 0 0.181"/><geometry><cylinder length="0.05" radius="0.025"/></geometry><material
    name="body_color"><color rgba="0 0.36862745098 0.721568627451 1.0"/></material></visual><collision><origin
    rpy="0 0 0" xyz="0 0 0.05"/><geometry><box size="0.1270 0.12 0.1"/></geometry></collision><inertial><mass
    value="1.0"/><origin xyz="0 0 0.05"/><inertia ixx="0.00217741666667" ixy="0.0"
    ixz="0.0" iyy="0.00254408333333" iyz="0.0" izz="0.00203333333333"/></inertial></link><joint
    name="top_box_step_j" type="fixed"><parent link="top_box"/><child link="top_box_step"/><origin
    rpy="0 0 0" xyz="0 0 0.06252"/></joint><link name="antenna"><visual><origin rpy="0
    0 0" xyz="0 0 0"/><geometry><mesh filename="package://nifti_robot_description/meshes/antenna.dae"
    scale="1.0 1.0 1.0"/></geometry></visual><collision><origin rpy="0 1.57079632679
    0" xyz="-0.01864 0 0"/><geometry><cylinder length="0.03718" radius="0.008"/></geometry></collision><collision><origin
    rpy="0 0 0" xyz="-0.030 0 0.19053"/><geometry><cylinder length="0.38107" radius="0.008"/></geometry></collision><inertial><origin
    rpy="0 0 0" xyz="-0.022 0.0203 0.02917"/><mass value="0.56"/><inertia ixx="0.004878"
    ixy="-6.2341e-07" ixz="-7.4538e-07" iyy="0.00090164" iyz="-0.00014394" izz="0.0042946"/></inertial></link><joint
    name="antenna_j" type="fixed"><parent link="base_link"/><child link="antenna"/><origin
    rpy="0 0 0" xyz="-0.1975 0.1 0.1551"/></joint><link name="gps_antenna"><visual><origin
    rpy="0 0 0" xyz="0 0 0.0"/><geometry><cylinder length="0.01" radius="0.05"/></geometry><material
    name="aluminium"><color rgba="0.8 0.8 0.8 1"/></material></visual><visual><origin
    rpy="0 0 0" xyz="0 0 -0.2"/><geometry><cylinder length="0.4" radius="0.03"/></geometry><material
    name="aluminium"><color rgba="0.8 0.8 0.8 1"/></material></visual><collision><origin
    rpy="0 0 0" xyz="0 0 0.0"/><geometry><cylinder length="0.01" radius="0.1"/></geometry></collision><collision><origin
    rpy="0 0 0" xyz="0 0 -0.2"/><geometry><cylinder length="0.4" radius="0.09"/></geometry></collision><inertial><origin
    rpy="0 0 0" xyz="-0.022 0.0203 0.02917"/><mass value="0.1"/><inertia ixx="0.004878"
    ixy="-6.2341e-07" ixz="-7.4538e-07" iyy="0.00090164" iyz="-0.00014394" izz="0.0042946"/></inertial></link><joint
    name="gps_antenna_j" type="fixed"><parent link="rear_right_box"/><child link="gps_antenna"/><origin
    rpy="0 0 0" xyz="0.03 0.11 0.405"/></joint><link name="dgps_main_antenna"><visual><origin
    rpy="0 0 0" xyz="0 0 0.0415"/><geometry><cylinder length="0.083" radius="0.02"/></geometry><material
    name="black_color"><color rgba="0.0 0.0 0.0 1.0"/></material></visual><collision><origin
    rpy="0 0 0" xyz="0 0 0.0415"/><geometry><cylinder length="0.083" radius="0.02"/></geometry></collision><inertial><mass
    value="0.035"/><origin rpy="0 0 0" xyz="0 0 0.0415"/><inertia ixx="2.35929166667e-05"
    ixy="0.0" ixz="0.0" iyy="2.35929166667e-05" iyz="0.0" izz="7e-06"/></inertial></link><joint
    name="dgps_main_antenna_j" type="fixed"><parent link="rear_right_box"/><child
    link="dgps_main_antenna"/><origin rpy="0.0 0.0 0.0" xyz="0.03 0.07 0.4"/></joint><link
    name="dgps_aux_antenna"><visual><origin rpy="0 0 0" xyz="0 0 0.0415"/><geometry><cylinder
    length="0.083" radius="0.02"/></geometry><material name="black_color"><color rgba="0.0
    0.0 0.0 1.0"/></material></visual><collision><origin rpy="0 0 0" xyz="0 0 0.0415"/><geometry><cylinder
    length="0.083" radius="0.02"/></geometry></collision><inertial><mass value="0.035"/><origin
    rpy="0 0 0" xyz="0 0 0.0415"/><inertia ixx="2.35929166667e-05" ixy="0.0" ixz="0.0"
    iyy="2.35929166667e-05" iyz="0.0" izz="7e-06"/></inertial></link><joint name="dgps_aux_antenna_j"
    type="fixed"><parent link="rear_right_box"/><child link="dgps_aux_antenna"/><origin
    rpy="0.0 0.0 0.0" xyz="0.57 0.1215 0.35"/></joint><link name="left_track"><visual><origin
    rpy="1.57 0 1.57" xyz="0 0 -0.0705"/><geometry><mesh filename="package://nifti_robot_description/meshes/bogie.dae"
    scale="1.0 1.0 1.0"/></geometry></visual><collision><origin rpy="1.57079632679
    0 1.57079632679" xyz="0 0 0.01855"/><geometry><box size="0.097000 0.178 0.500000"/></geometry></collision><collision><origin
    rpy="1.57079632679 0 0" xyz="0.25 -0.015 0.01855"/><geometry><cylinder length="0.112"
    radius="0.089000"/></geometry></collision><collision><origin rpy="1.57079632679
    0 0" xyz="-0.25 0 0.01855"/><geometry><cylinder length="0.097000" radius="0.089000"/></geometry></collision><inertial><origin
    rpy="0 0 0" xyz="0 0 0.0141"/><mass value="6.06"/><inertia ixx="0.002731" ixy="0.0"
    ixz="0.0" iyy="0.032554" iyz="1.5e-05" izz="0.031391"/></inertial></link><joint
    name="left_track_j" type="revolute"><parent link="base_link"/><child link="left_track"/><axis
    xyz="0 1 0"/><origin rpy="0 0.0 0" xyz="0 0.1985 0"/><limit effort="0" lower="-0.7"
    upper="0.7" velocity="4"/></joint><link name="right_track"><visual><origin rpy="1.57
    0 -1.57" xyz="0 0 -0.0705"/><geometry><mesh filename="package://nifti_robot_description/meshes/bogie.dae"
    scale="1.0 1.0 1.0"/></geometry></visual><collision><origin rpy="1.57079632679
    0 1.57079632679" xyz="0 0 0.01855"/><geometry><box size="0.097000 0.178 0.500000"/></geometry></collision><collision><origin
    rpy="1.57079632679 0 0" xyz="0.25 0.015 0.01855"/><geometry><cylinder length="0.112"
    radius="0.089000"/></geometry></collision><collision><origin rpy="1.57079632679
    0 0" xyz="-0.25 0 0.01855"/><geometry><cylinder length="0.097000" radius="0.089000"/></geometry></collision><inertial><origin
    rpy="0 0 0" xyz="0 0 0.0141"/><mass value="6.06"/><inertia ixx="0.002731" ixy="0.0"
    ixz="0.0" iyy="0.032554" iyz="1.5e-05" izz="0.031391"/></inertial></link><joint
    name="right_track_j" type="revolute"><parent link="base_link"/><child link="right_track"/><axis
    xyz="0 1 0"/><origin rpy="0 0.0 0" xyz="0 -0.1985 0"/><mimic joint="left_track_j"
    multiplier="-1"/><limit effort="0" lower="-0.7" upper="0.7" velocity="4"/></joint><link
    name="front_left_flipper"><visual><origin rpy="3.32575 0 1.57079632679" xyz="0
    0 0"/><geometry><mesh filename="package://nifti_robot_description/meshes/flipper.dae"
    scale="1.0 1.0 1.0"/></geometry></visual><collision name="front_left_flipper_collision_large_wheel"><origin
    rpy="1.57079632679 0 0" xyz="0 -0.0 0"/><geometry><cylinder length="0.04981" radius="0.089000"/></geometry></collision><collision
    name="front_left_flipper_collision_small_wheel"><origin rpy="1.57079632679 0 0"
    xyz="0.33 -0.0 0.0"/><geometry><cylinder length="0.04981" radius="0.0435"/></geometry></collision><collision
    name="front_left_flipper_collision_top_bar"><origin rpy="0 0.184162095 0.0" xyz="0.165
    -0.0 0.0325"/><geometry><box size="0.330000 0.04981 0.0825"/></geometry></collision><collision
    name="front_left_flipper_collision_bottom_bar"><origin rpy="0 -0.184162095 0.0"
    xyz="0.165 -0.0 -0.0325"/><geometry><box size="0.330000 0.04981 0.0825"/></geometry></collision><collision
    name="front_left_flipper_collision_middle_bar"><origin rpy="0 -0.02 0.0" xyz="0.166
    -0.0 0.004"/><geometry><box size="0.20 0.04981 0.07"/></geometry></collision><inertial><origin
    rpy="0 0 0" xyz="0.08 0 0.0"/><mass value="0.75"/><inertia ixx="0.0017491" ixy="2.8512e-07"
    ixz="0.0018277" iyy="0.012277" iyz="-3.6288e-07" izz="0.010941"/></inertial><sensor
    name="front_left_flipper_contact" type="contact"><contact><collision>front_left_flipper_collision</collision><collision>front_left_flipper_collision_large_wheel</collision><collision>front_left_flipper_collision_small_wheel</collision><collision>front_left_flipper_collision_top_bar</collision><collision>front_left_flipper_collision_bottom_bar</collision><collision>front_left_flipper_collision_middle_bar</collision></contact></sensor></link><joint
    name="front_left_flipper_j" type="continuous"><parent link="left_track"/><child
    link="front_left_flipper"/><axis xyz="0 1 0"/><origin rpy="0 0.193732 0" xyz="0.25
    0.0735 0.0195"/></joint><link name="front_left_flipper_end_point"/><joint name="front_left_flipper_end_point_j"
    type="fixed"><parent link="front_left_flipper"/><child link="front_left_flipper_end_point"/><origin
    rpy="0 0.193732 0" xyz="0.3476 0 0"/></joint><link name="front_right_flipper"><visual><origin
    rpy="3.32575 0 -1.57079632679" xyz="0 0 0"/><geometry><mesh filename="package://nifti_robot_description/meshes/flipper.dae"
    scale="1.0 1.0 1.0"/></geometry></visual><collision name="front_right_flipper_collision_large_wheel"><origin
    rpy="1.57079632679 0 0" xyz="0 0.0 0"/><geometry><cylinder length="0.04981" radius="0.089000"/></geometry></collision><collision
    name="front_right_flipper_collision_small_wheel"><origin rpy="1.57079632679 0
    0" xyz="-0.33 0.0 0.0"/><geometry><cylinder length="0.04981" radius="0.0435"/></geometry></collision><collision
    name="front_right_flipper_collision_top_bar"><origin rpy="0 0.184162095 3.14159265359"
    xyz="-0.165 0.0 0.0325"/><geometry><box size="0.330000 0.04981 0.0825"/></geometry></collision><collision
    name="front_right_flipper_collision_bottom_bar"><origin rpy="0 -0.184162095 3.14159265359"
    xyz="-0.165 0.0 -0.0325"/><geometry><box size="0.330000 0.04981 0.0825"/></geometry></collision><collision
    name="front_right_flipper_collision_middle_bar"><origin rpy="0 -0.02 3.14159265359"
    xyz="-0.166 0.0 0.004"/><geometry><box size="0.20 0.04981 0.07"/></geometry></collision><inertial><origin
    rpy="0 0 0" xyz="-0.08 0 0.0"/><mass value="0.75"/><inertia ixx="0.0017491" ixy="2.8512e-07"
    ixz="0.0018277" iyy="0.012277" iyz="-3.6288e-07" izz="0.010941"/></inertial><sensor
    name="front_right_flipper_contact" type="contact"><contact><collision>front_right_flipper_collision</collision><collision>front_right_flipper_collision_large_wheel</collision><collision>front_right_flipper_collision_small_wheel</collision><collision>front_right_flipper_collision_top_bar</collision><collision>front_right_flipper_collision_bottom_bar</collision><collision>front_right_flipper_collision_middle_bar</collision></contact></sensor></link><joint
    name="front_right_flipper_j" type="continuous"><parent link="right_track"/><child
    link="front_right_flipper"/><axis xyz="0 1 0"/><origin rpy="0 -2.94786065359 0"
    xyz="0.25 -0.0735 0.0195"/></joint><link name="front_right_flipper_end_point"/><joint
    name="front_right_flipper_end_point_j" type="fixed"><parent link="front_right_flipper"/><child
    link="front_right_flipper_end_point"/><origin rpy="0 0.193732 0" xyz="-0.3476
    0 0"/></joint><link name="rear_left_flipper"><visual><origin rpy="3.32575 0 1.57079632679"
    xyz="0 0 0"/><geometry><mesh filename="package://nifti_robot_description/meshes/flipper.dae"
    scale="1.0 1.0 1.0"/></geometry></visual><collision name="rear_left_flipper_collision_large_wheel"><origin
    rpy="1.57079632679 0 0" xyz="0 -0.0 0"/><geometry><cylinder length="0.04981" radius="0.089000"/></geometry></collision><collision
    name="rear_left_flipper_collision_small_wheel"><origin rpy="1.57079632679 0 0"
    xyz="0.33 -0.0 0.0"/><geometry><cylinder length="0.04981" radius="0.029"/></geometry></collision><collision
    name="rear_left_flipper_collision_top_bar"><origin rpy="0 0.184162095 0.0" xyz="0.165
    -0.0 0.0325"/><geometry><box size="0.330000 0.04981 0.055"/></geometry></collision><collision
    name="rear_left_flipper_collision_bottom_bar"><origin rpy="0 -0.184162095 0.0"
    xyz="0.165 -0.0 -0.0325"/><geometry><box size="0.330000 0.04981 0.055"/></geometry></collision><collision
    name="rear_left_flipper_collision_middle_bar"><origin rpy="0 -0.02 0.0" xyz="0.166
    -0.0 0.004"/><geometry><box size="0.20 0.04981 0.07"/></geometry></collision><inertial><origin
    rpy="0 0 0" xyz="0.08 0 0.0"/><mass value="0.75"/><inertia ixx="0.0017491" ixy="2.8512e-07"
    ixz="0.0018277" iyy="0.012277" iyz="-3.6288e-07" izz="0.010941"/></inertial><sensor
    name="rear_left_flipper_contact" type="contact"><contact><collision>rear_left_flipper_collision</collision><collision>rear_left_flipper_collision_large_wheel</collision><collision>rear_left_flipper_collision_small_wheel</collision><collision>rear_left_flipper_collision_top_bar</collision><collision>rear_left_flipper_collision_bottom_bar</collision><collision>rear_left_flipper_collision_middle_bar</collision></contact></sensor></link><joint
    name="rear_left_flipper_j" type="continuous"><parent link="left_track"/><child
    link="rear_left_flipper"/><axis xyz="0 1 0"/><origin rpy="0 2.94786065359 0" xyz="-0.25
    0.0735 0.0195"/></joint><link name="rear_left_flipper_end_point"/><joint name="rear_left_flipper_end_point_j"
    type="fixed"><parent link="rear_left_flipper"/><child link="rear_left_flipper_end_point"/><origin
    rpy="0 0.193732 0" xyz="0.3476 0 0"/></joint><link name="rear_right_flipper"><visual><origin
    rpy="3.32575 0 -1.57079632679" xyz="0 0 0"/><geometry><mesh filename="package://nifti_robot_description/meshes/flipper.dae"
    scale="1.0 1.0 1.0"/></geometry></visual><collision name="rear_right_flipper_collision_large_wheel"><origin
    rpy="1.57079632679 0 0" xyz="0 0.0 0"/><geometry><cylinder length="0.04981" radius="0.089000"/></geometry></collision><collision
    name="rear_right_flipper_collision_small_wheel"><origin rpy="1.57079632679 0 0"
    xyz="-0.33 0.0 0.0"/><geometry><cylinder length="0.04981" radius="0.029"/></geometry></collision><collision
    name="rear_right_flipper_collision_top_bar"><origin rpy="0 0.184162095 3.14159265359"
    xyz="-0.165 0.0 0.0325"/><geometry><box size="0.330000 0.04981 0.055"/></geometry></collision><collision
    name="rear_right_flipper_collision_bottom_bar"><origin rpy="0 -0.184162095 3.14159265359"
    xyz="-0.165 0.0 -0.0325"/><geometry><box size="0.330000 0.04981 0.055"/></geometry></collision><collision
    name="rear_right_flipper_collision_middle_bar"><origin rpy="0 -0.02 3.14159265359"
    xyz="-0.166 0.0 0.004"/><geometry><box size="0.20 0.04981 0.07"/></geometry></collision><inertial><origin
    rpy="0 0 0" xyz="-0.08 0 0.0"/><mass value="0.75"/><inertia ixx="0.0017491" ixy="2.8512e-07"
    ixz="0.0018277" iyy="0.012277" iyz="-3.6288e-07" izz="0.010941"/></inertial><sensor
    name="rear_right_flipper_contact" type="contact"><contact><collision>rear_right_flipper_collision</collision><collision>rear_right_flipper_collision_large_wheel</collision><collision>rear_right_flipper_collision_small_wheel</collision><collision>rear_right_flipper_collision_top_bar</collision><collision>rear_right_flipper_collision_bottom_bar</collision><collision>rear_right_flipper_collision_middle_bar</collision></contact></sensor></link><joint
    name="rear_right_flipper_j" type="continuous"><parent link="right_track"/><child
    link="rear_right_flipper"/><axis xyz="0 1 0"/><origin rpy="0 -0.193732 0" xyz="-0.25
    -0.0735 0.0195"/></joint><link name="rear_right_flipper_end_point"/><joint name="rear_right_flipper_end_point_j"
    type="fixed"><parent link="rear_right_flipper"/><child link="rear_right_flipper_end_point"/><origin
    rpy="0 0.193732 0" xyz="-0.3476 0 0"/></joint><link name="imu"><inertial><origin
    rpy="0 0 0" xyz="0 0 0"/><mass value="1e-5"/><inertia ixx="1e-3" ixy="1e-6" ixz="1e-6"
    iyy="1e-3" iyz="1e-6" izz="1e-3"/></inertial></link><joint name="imu_j" type="fixed"><parent
    link="base_link"/><child link="imu"/><origin rpy="3.14159265359 0 -1.57079632679"
    xyz="0 0 0.1500"/></joint><link name="camera_0"><inertial><origin rpy="0 0 0"
    xyz="0 0 0"/><mass value="1e-5"/><inertia ixx="1e-3" ixy="1e-6" ixz="1e-6" iyy="1e-3"
    iyz="1e-6" izz="1e-3"/></inertial></link><link name="camera_front"><inertial><origin
    rpy="0 0 0" xyz="0 0 0"/><mass value="1e-5"/><inertia ixx="1e-3" ixy="1e-6" ixz="1e-6"
    iyy="1e-3" iyz="1e-6" izz="1e-3"/></inertial></link><joint name="camera_0_j" type="fixed"><parent
    link="rear_right_box"/><child link="camera_front"/><origin rpy="0.0 -0.0 0.0"
    xyz="0.6 0.1215 0.02"/></joint><joint name="camera_front_optical_j" type="fixed"><parent
    link="camera_front"/><child link="camera_0"/><origin rpy="-1.57079632679 0 -1.57079632679"
    xyz="0 0 0"/></joint><link name="camera_1"><inertial><origin rpy="0 0 0" xyz="0
    0 0"/><mass value="1e-5"/><inertia ixx="1e-3" ixy="1e-6" ixz="1e-6" iyy="1e-3"
    iyz="1e-6" izz="1e-3"/></inertial></link><link name="camera_right"><inertial><origin
    rpy="0 0 0" xyz="0 0 0"/><mass value="1e-5"/><inertia ixx="1e-3" ixy="1e-6" ixz="1e-6"
    iyy="1e-3" iyz="1e-6" izz="1e-3"/></inertial></link><joint name="camera_1_j" type="fixed"><parent
    link="rear_right_box"/><child link="camera_left"/><origin rpy="0.0 -0.0 1.57079632679"
    xyz="0.3 0.223 0.02"/></joint><joint name="camera_right_optical_j" type="fixed"><parent
    link="camera_right"/><child link="camera_1"/><origin rpy="-1.57079632679 0 -1.57079632679"
    xyz="0 0 0"/></joint><link name="camera_2"><inertial><origin rpy="0 0 0" xyz="0
    0 0"/><mass value="1e-5"/><inertia ixx="1e-3" ixy="1e-6" ixz="1e-6" iyy="1e-3"
    iyz="1e-6" izz="1e-3"/></inertial></link><link name="camera_rear"><inertial><origin
    rpy="0 0 0" xyz="0 0 0"/><mass value="1e-5"/><inertia ixx="1e-3" ixy="1e-6" ixz="1e-6"
    iyy="1e-3" iyz="1e-6" izz="1e-3"/></inertial></link><joint name="camera_2_j" type="fixed"><parent
    link="rear_right_box"/><child link="camera_rear"/><origin rpy="0.0 -0.0 3.14159265359"
    xyz="0.02 0.1215 0.02"/></joint><joint name="camera_rear_optical_j" type="fixed"><parent
    link="camera_rear"/><child link="camera_2"/><origin rpy="-1.57079632679 0 -1.57079632679"
    xyz="0 0 0"/></joint><link name="camera_3"><inertial><origin rpy="0 0 0" xyz="0
    0 0"/><mass value="1e-5"/><inertia ixx="1e-3" ixy="1e-6" ixz="1e-6" iyy="1e-3"
    iyz="1e-6" izz="1e-3"/></inertial></link><link name="camera_left"><inertial><origin
    rpy="0 0 0" xyz="0 0 0"/><mass value="1e-5"/><inertia ixx="1e-3" ixy="1e-6" ixz="1e-6"
    iyy="1e-3" iyz="1e-6" izz="1e-3"/></inertial></link><joint name="camera_3_j" type="fixed"><parent
    link="rear_right_box"/><child link="camera_right"/><origin rpy="0.0 -0.0 -1.57079632679"
    xyz="0.3 0.02 0.02"/></joint><joint name="camera_left_optical_j" type="fixed"><parent
    link="camera_left"/><child link="camera_3"/><origin rpy="-1.57079632679 0 -1.57079632679"
    xyz="0 0 0"/></joint><link name="camera_4"><inertial><origin rpy="0 0 0" xyz="0
    0 0"/><mass value="1e-5"/><inertia ixx="1e-3" ixy="1e-6" ixz="1e-6" iyy="1e-3"
    iyz="1e-6" izz="1e-3"/></inertial></link><link name="camera_top"><inertial><origin
    rpy="0 0 0" xyz="0 0 0"/><mass value="1e-5"/><inertia ixx="1e-3" ixy="1e-6" ixz="1e-6"
    iyy="1e-3" iyz="1e-6" izz="1e-3"/></inertial></link><joint name="camera_4_j" type="fixed"><parent
    link="rear_right_box"/><child link="camera_top"/><origin rpy="-0.0 -1.57079632679
    0.0" xyz="0.48 0.1215 0.25"/></joint><joint name="camera_top_optical_j" type="fixed"><parent
    link="camera_top"/><child link="camera_4"/><origin rpy="-1.57079632679 0 -1.57079632679"
    xyz="0 0 0"/></joint></robot>'}
ntrip_relay: {host: ntrip.pecny.cz, num_threads: 2, port: 2101, sigkill_on_stream_stop: true,
  sigkill_timeout: 30}
odom2d: {integration_method: EulerIMU, odom_frame: odom}
omnicam_sensors_calib:
  transforms:
  - [0.6, 0.1215, 0.02, 0.0, 0.0, 0.0, 1.0, rear_right_box, camera_front]
  - [0.3, 0.02, 0.02, 0.0, 0.0, 0.7071, -0.7071, rear_right_box, camera_right]
  - [0.02, 0.1215, 0.02, 0.0, 0.0, 1.0, 0.0, rear_right_box, camera_rear]
  - [0.3, 0.223, 0.02, 0.0, 0.0, 0.7071, 0.7071, rear_right_box, camera_left]
  - [0.48, 0.1215, 0.25, 0.0, 0.7071, 0.0, -0.7071, rear_right_box, camera_top]
os_cloud_node:
  fields_to_publish: [t, intensity, ambient, reflectivity]
  keep_organized: true
  max_range: 50.0
  publish_2nd_cloud: false
  publish_2nd_invalid: false
  publish_2nd_scans: false
  publish_cloud: true
  publish_invalid: true
  publish_scans: false
  standardize_invalid_measurements: false
  tf_prefix: ''
  unalign_fields: false
os_node: {allow_automotive_slave_resync: true, allow_local_timestamping: true, imu_port: 0,
  lidar_port: 0, max_ptp_offset: 0.002, max_secs_without_data: 0, multipurpose_io_mode: OUTPUT_FROM_ENCODER_ANGLE,
  publish_every_nth: 1, sensor_hostname: os-992107000600.local, sync_pulse_out_polarity: ACTIVE_LOW,
  timestamp_mode: TIME_FROM_PTP_1588, udp_profile_lidar: RNG19_RFL8_SIG16_NIR16}
parts_config: {axis_x_offset: 0.059, axis_y_offset: 0.08, battery_cover_height: 0.067,
  battery_cover_x: 0.225, battery_mass: 2.7, big_collision_box_height: 0.35, big_collision_box_length: 0.6,
  big_collision_box_on_top: true, big_collision_box_width: 0.5, big_collision_box_x: 0.0,
  body_mass: 10.0, dgps_antenna_height: 0.083, dgps_antenna_radius: 0.02, flipper_inflation_ratio: 1.5,
  flipper_inward_enlargement: 0.0, gps_antenna_disc_radius: 0.05, gps_antenna_height: 0.4,
  gps_antenna_radius: 0.03, has_axis_camera: false, has_battery_cover: true, has_dgps_antennas: true,
  has_directional_gps_antennas: false, has_flipper_touch_sensors: false, has_gps_antenna: true,
  has_jetson: false, has_mobilicom: false, has_mote_deployer: false, has_new_realsense: false,
  has_omnicam: false, has_omnicam_sensor_mount: false, has_omnicam_vras: true, has_ouster_lidar: true,
  has_ptuxthermo: false, has_realsense: false, has_realsense_d435: false, has_realsense_t265: false,
  has_rear_sensor_item: false, has_sick_lidar: false, has_top_box: true, has_velodyne: false,
  jetson_shift_x: 0.515, jetson_shift_y: 0.145, jetson_version: 1, jetson_yaw: 0.0,
  laser_pitch: 0.0, mobilicom_antenna_l_rotation: -0.5, mobilicom_antenna_l_tilt: 1.0,
  mobilicom_antenna_r_rotation: 0.0, mobilicom_antenna_r_tilt: 1.5758, mobilicom_antennas_length: 0.17,
  mobilicom_has_antenna_box: false, mobilicom_is_lite: true, mobilicom_parent_link: rear_right_box,
  mobilicom_pitch: 4.0, mobilicom_roll: 1.5758, mobilicom_shift_x: 0.0, mobilicom_shift_y: 0.01,
  mobilicom_shift_z: 0.2, mobilicom_yaw: 3.14152, ptuxthermo_x_offset: 0.2, ptuxthermo_y_offset: 0.18,
  realsense_holder_version: 1, realsense_parent_link: omnicam, realsense_roll: 0.0,
  realsense_shift_x: 0.0, realsense_shift_y: 0.0, realsense_shift_z: 0.0, realsense_tilt: -1.15,
  realsense_yaw: 0.62831853, revision: 2021, robot_type: nifti, t265_parent_link: rear_sensor_item,
  top_box_ant_l_wifi_angle: 0.0, top_box_ant_l_wifi_length: 0.13, top_box_ant_l_wifi_y: 0.047,
  top_box_ant_l_wifi_z: 0.02, top_box_ant_lora_angle: 0.0, top_box_ant_lora_length: 0.11,
  top_box_ant_lora_y: -0.1, top_box_ant_lora_z: 0.08, top_box_ant_r_wifi_angle: 0.0,
  top_box_ant_r_wifi_length: 0.13, top_box_ant_r_wifi_y: -0.047, top_box_ant_r_wifi_z: 0.02,
  top_box_j_x: 0.504, velodyne_x_offset: 0.41, velodyne_yaw: -1.84}
points_filtered_throttle: {frequency: 2.0}
points_slow_jetson: {frequency: 2.0}
points_slow_kontron: {frequency: 2.0}
points_throttle: {frequency: 2.0}
remote_teleop_joy_clone_robot_14840_2123088246182336023:
  at_red_button: 2
  at_right_axis_button_id: 11
  at_yellow_button: 3
  axis_angular: 0
  axis_linear: 1
  deadman_buttons: [1, 10]
  differential_brake_button: 8
  enable_button: 9
  estop_button: 8
  flipper_axis: 5
  flipper_increment: 0.3490658503988659
  flipper_reset_button: 3
  front_left_flipper_button: 4
  front_light_button_1: 4
  front_light_button_2: 9
  front_right_flipper_button: 5
  plugin_pkg: nifti_teleop_joy
  priority: local_joy
  rear_left_flipper_button: 6
  rear_right_flipper_button: 7
  run_button: 0
  scanning_speed_axis: 4
  scanning_speed_increment: 0.2
  servo_reset_button_1: 6
  servo_reset_button_2: 7
  servo_reset_button_3: 8
  servo_reset_button_4: 9
  side_light_button_1: 5
  side_light_button_2: 9
remote_teleop_joy_clone_robot_14840_8606553020759958422:
  at_red_button: 2
  at_right_axis_button_id: 11
  at_yellow_button: 3
  axis_angular: 0
  axis_linear: 1
  deadman_buttons: [1, 10]
  differential_brake_button: 8
  enable_button: 9
  estop_button: 8
  flipper_axis: 5
  flipper_increment: 0.3490658503988659
  flipper_reset_button: 3
  front_left_flipper_button: 4
  front_light_button_1: 4
  front_light_button_2: 9
  front_right_flipper_button: 5
  plugin_pkg: nifti_teleop_joy
  priority: secondary_joy
  rear_left_flipper_button: 6
  rear_right_flipper_button: 7
  run_button: 0
  scanning_speed_axis: 4
  scanning_speed_increment: 0.2
  servo_reset_button_1: 6
  servo_reset_button_2: 7
  servo_reset_button_3: 8
  servo_reset_button_4: 9
  side_light_button_1: 5
  side_light_button_2: 9
remote_teleop_joy_clone_robot_3087_64389318954454393:
  at_red_button: 2
  at_right_axis_button_id: 11
  at_yellow_button: 3
  axis_angular: 0
  axis_linear: 1
  deadman_buttons: [1, 10]
  differential_brake_button: 8
  enable_button: 9
  estop_button: 8
  flipper_axis: 5
  flipper_increment: 0.3490658503988659
  flipper_reset_button: 3
  front_left_flipper_button: 4
  front_light_button_1: 4
  front_light_button_2: 9
  front_right_flipper_button: 5
  plugin_pkg: nifti_teleop_joy
  priority: secondary_joy
  rear_left_flipper_button: 6
  rear_right_flipper_button: 7
  run_button: 0
  scanning_speed_axis: 4
  scanning_speed_increment: 0.2
  servo_reset_button_1: 6
  servo_reset_button_2: 7
  servo_reset_button_3: 8
  servo_reset_button_4: 9
  side_light_button_1: 5
  side_light_button_2: 9
remote_teleop_joy_clone_robot_3087_8275679463272632777:
  at_red_button: 2
  at_right_axis_button_id: 11
  at_yellow_button: 3
  axis_angular: 0
  axis_linear: 1
  deadman_buttons: [1, 10]
  differential_brake_button: 8
  enable_button: 9
  estop_button: 8
  flipper_axis: 5
  flipper_increment: 0.3490658503988659
  flipper_reset_button: 3
  front_left_flipper_button: 4
  front_light_button_1: 4
  front_light_button_2: 9
  front_right_flipper_button: 5
  plugin_pkg: nifti_teleop_joy
  priority: local_joy
  rear_left_flipper_button: 6
  rear_right_flipper_button: 7
  run_button: 0
  scanning_speed_axis: 4
  scanning_speed_increment: 0.2
  servo_reset_button_1: 6
  servo_reset_button_2: 7
  servo_reset_button_3: 8
  servo_reset_button_4: 9
  side_light_button_1: 5
  side_light_button_2: 9
rosdistro: 'melodic

  '
roslaunch:
  uris: {host_clone_robot__32773: 'http://clone-robot:32773/', host_clone_robot__34679: 'http://clone-robot:34679/',
    host_clone_robot__34843: 'http://clone-robot:34843/', host_clone_robot__36143: 'http://clone-robot:36143/',
    host_clone_robot__37263: 'http://clone-robot:37263/', host_clone_robot__38655: 'http://clone-robot:38655/',
    host_clone_robot__39109: 'http://clone-robot:39109/', host_clone_robot__39415: 'http://clone-robot:39415/',
    host_clone_robot__40575: 'http://clone-robot:40575/', host_clone_robot__42733: 'http://clone-robot:42733/',
    host_clone_robot__43211: 'http://clone-robot:43211/', host_clone_robot__44381: 'http://clone-robot:44381/',
    host_clone_robot__44709: 'http://clone-robot:44709/', host_clone_robot__45363: 'http://clone-robot:45363/',
    host_clone_robot__45995: 'http://clone-robot:45995/', host_clone_robot__46179: 'http://clone-robot:46179/',
    host_clone_robot__46367: 'http://clone-robot:46367/'}
rosversion: '1.14.13

  '
rover: {bodyEdgeCurvature: 0.035, flipperBeltThickness: 0.03, flipperLength: 0.33,
  flipperOffset: 0.193731547, flipperWidth: 0.04981, maxScanningSpeed: 1.2, referentialZ: 0.0705,
  robotBodyShift: 0, robotLengthBody: 0.635, robotWidthBody: 0.243, robotWidthFlippers: 0.594,
  robotWidthTracks: 0.494, trackDistance: 0.397, trackLength: 0.5, trackWheelRadius: 0.089,
  trackWidth: 0.097, vMax: 0.6, vMaxRun: 0.6, vMaxTravel: 0.3, wMax: 3.02, wMaxRun: 1.24,
  wMaxTravel: 0.6}
run_id: b3596e7e-7bf3-11ef-a7b4-00133b4a6ee5
static_transforms: []
steering_efficiency: 0.5
system_monitor:
  ntp_monitor: {reference_host: ntp.nic.cz}
  test:
    cpu_monitor: {check_core_temps: true, cpu_load1_warn: 0.9, cpu_load5_warn: 0.8,
      cpu_load_error: 1.0, cpu_load_warn: 0.9, cpu_temp_error: 90.0, cpu_temp_warn: 85.0}
    hdd_monitor: {hdd_level_error: 0.99, hdd_level_warn: 0.95, hdd_temp_error: 70.0,
      hdd_temp_warn: 55.0, no_hdd_temp: true, no_hdd_temp_warn: false}
    mem_monitor: {mem_level_error: 0.99, mem_level_warn: 0.95}
    net_capacity: 128.0
    net_monitor: {net_level_warn: 0.95}
    ntp_monitor: {error_offset_tolerance: 5000000.0, offset_tolerance: 500.0, reference_host: ntp.nic.cz}
tf:
  buffer_size: 30.0
  publish_frame_service: true
  server:
    streams:
      body:
        allow_transforms_update: true
        child_frames: []
        intermediate_frames: true
        parent_frame: base_link
        publication_period: 0.02
        publisher_queue_size: 100
      laser:
        allow_transforms_update: true
        child_frames: [laser]
        intermediate_frames: true
        parent_frame: odom
        publication_period: 0.02
        publisher_queue_size: 10
      odom:
        allow_transforms_update: true
        child_frames: [base_link]
        intermediate_frames: true
        parent_frame: odom
        publication_period: 0.02
        publisher_queue_size: 10
    supports_transform_streams: true
    transforms_update_period: 10.0
  use_node_namespace: true
tf_static_publisher:
  reload_frequency: 0.03
  transforms:
  - [-0.216, 0.035, 0.231, -0.259, -0.141, 0.904, 0.31, base_link, markers]
tracks_reset_service_name: gpio_set_sw_2
viz:
  camera1394_driver: {guid: ''}
  lady_saw: {camera_name_format: _1232x1616_c%i}
